Workbook

Sheet 总览
A1: 股票代码 | B1: 事件ID | C1: 事件日期 | D1: 有效交易日(T0) | E1: 标题 | F1: 事件来源 | G1: 事件类型 | H1: 行业 | I1: 行情起始 | J1: 行情结束 | K1: 样本天数 | L1: 前窗口覆盖 | M1: 后窗口覆盖 | N1: 状态说明
A2: 000063.SZ | B2: 11 | C2: 45362 | D2: 45362 | E2: 2023年年度报告点评：“连接+算力”拓展深化，增长仍为第一要义 | F2: 东方财富 | G2: 技术 | H2: 算力 | I2: 45271 | J2: 45366 | K2: 63 | L2: 58 | M2: 4 | N2: 前100日不完整；后5日不完整
A3: 000925.SZ | B3: 2 | C3: 45302 | D3: 45302 | E3: 众合科技： 关于公司算力战略合作框架协议的实施进展公告（三） | F3: 巨潮资讯 | G3: 公司行为 | H3: 算力 | I3: 45180 | J3: 45307 | K3: 85 | L3: 81 | M3: 3 | N3: 前100日不完整；后5日不完整
A4: 002685.SZ | B4: 21 | C4: 45907 | D4: 45908 | E4: 港机订单稳定向好，布局GPU打造新成长极 | F4: 东方财富 | G4: 技术 | H4: GPU | I4: 45817 | J4: 45912 | K4: 70 | L4: 65 | M4: 4 | N4: 事件日顺延到下一交易日；前100日不完整；后5日不完整
A5: 300054.SZ | B5: 42 | C5: 45344 | D5: 45344 | E5: 鼎龙股份半导体材料营收同比增长，新品研发及导入进展顺利 | F5: 东方财富 | G5: 技术 | H5: 半导体 | I5: 45252 | J5: 45349 | K5: 63 | L5: 59 | M5: 3 | N5: 前100日不完整；后5日不完整
A6: 300474.SZ | B6: 22 | C6: 45876 | D6: 45876 | E6: 显卡、通用GPU双线布局，管理变革推动创新 | F6: 东方财富 | G6: 技术 | H6: GPU | I6: 45784 | J6: 45881 | K6: 69 | L6: 65 | M6: 3 | N6: 前100日不完整；后5日不完整
A7: 300496.SZ | B7: 35 | C7: 45159 | D7: 45159 | E7: 智能汽车保持高增，大模型+边缘计算彰显长期价值 | F7: 东方财富 | G7: 技术 | H7: 边缘计算 | I7: 45068 | J7: 45163 | K7: 68 | L7: 63 | M7: 4 | N7: 前100日不完整；后5日不完整
A8: 300571.SZ | B8: 29 | C8: 45803 | D8: 45803 | E8: 平治信息： 关于陕西电信GPU算力建设项目进展暨签订框架协议的公告 | F8: 巨潮资讯 | G8: 公司行为 | H8: GPU | I8: 45714 | J8: 45807 | K8: 64 | L8: 59 | M8: 4 | N8: 前100日不完整；后5日不完整
A9: 300638.SZ | B9: 36 | C9: 45063 | D9: 45063 | E9: 深度报告：5G+AI时代下的连接与边缘计算旗手 | F9: 东方财富 | G9: 技术 | H9: 边缘计算 | I9: 44974 | J9: 45068 | K9: 63 | L9: 59 | M9: 3 | N9: 前100日不完整；后5日不完整
A10: 300738.SZ | B10: 40 | C10: 45532 | D10: 45532 | E10: 关于数据中心获得2023年度碳中和认证的公告 | F10: 巨潮资讯 | G10: 公司行为 | H10: 数据中心 | I10: 45440 | J10: 45539 | K10: 71 | L10: 65 | M10: 5 | N10: 前100日不完整
A11: 600821.SH | B11: 4 | C11: 45873 | D11: 45873 | E11: 金开新能： 关于全资子公司人工智能算力技术服务合同的进展公告 | F11: 巨潮资讯 | G11: 公司行为 | H11: 算力 | I11: 45783 | J11: 45877 | K11: 68 | L11: 63 | M11: 4 | N11: 前100日不完整；后5日不完整
A12: 600941.SH | B12: 14 | C12: 45770 | D12: 45770 | E12: AI业务接力成长，加速智算建设 | F12: 东方财富 | G12: 技术 | H12: 算力 | I12: 45680 | J12: 45775 | K12: 61 | L12: 57 | M12: 3 | N12: 前100日不完整；后5日不完整
A13: 603019.SH | B13: 12 | C13: 45527 | D13: 45527 | E13: 2024半年报点评：业绩稳健增长，算力建设稳步推进 | F13: 东方财富 | G13: 技术 | H13: 算力 | I13: 45435 | J13: 45532 | K13: 69 | L13: 65 | M13: 3 | N13: 前100日不完整；后5日不完整
... A24: 600186.SH | B24: 3 | C24: 45563 | D24: 45565 | E24: 莲花控股： 莲花控股股份有限公司关于转型算力业务相关进展情况的公告 | F24: 巨潮资讯 | G24: 公司行为 | H24: 算力 | I24: 45461 | J24: 45580 | K24: 79 | L24: 72 | M24: 6 | N24: 事件日顺延到下一交易日；前100日不完整

Sheet 000063.SZ_元数据
A1: 字段 | B1: 内容
A2: 股票代码 | B2: 000063.SZ
A3: 事件名称 | B3: 2023年年度报告点评：“连接+算力”拓展深化，增长仍为第一要义
A4: 事件日期 | B4: 45362
A5: 数据来源 | B5: 用户提供行情CSV + 事件库1.csv
A6: 分类规则 | B6: 前100个交易日 / 事件当日 / 后5个交易日
A7: 事件ID | B7: 11
A8: 内容链接 | B8: https://data.eastmoney.com/report/zw_stock.jshtml?infocode=AP202403111626215378
A9: 事件来源 | B9: 东方财富
A10: 事件类型 | B10: 技术
A11: 行业 | B11: 算力
A12: 有效交易日(T0) | B12: 45362
A13: 窗口覆盖说明 | B13: 前窗口覆盖 58/100 个交易日；后窗口覆盖 4/5 个交易日
A14: 说明 | B14: 若事件日期不是交易日，则 T0 取事件日期之后的首个交易日。

Sheet 000063.SZ_行情
A1: ts_code | B1: trade_date | C1: open | D1: high | E1: low | F1: close | G1: pre_close | H1: change | I1: pct_chg | J1: vol | K1: amount | L1: 数据来源 | M1: 数据分类 | N1: 事件日期 | O1: 交易日序号 | P1: 事件交易日序号 | Q1: 相对交易日 | R1: 窗口标签 | S1: 备注
A2: 000063.SZ | B2: 45271 | C2: 25.9 | D2: 26.62 | E2: 25.51 | F2: 26.57 | G2: 26.1 | H2: 0.47 | I2: 1.8008 | J2: 960616.03 | K2: 2507913.6 | L2: 用户提供行情CSV | M2: 股票日行情 | N2: 45362 | O2: 1 | P2: 59 | Q2: -58 | R2: 事件前100个交易日
A3: 000063.SZ | B3: 45272 | C3: 26.45 | D3: 26.78 | E3: 26.2 | F3: 26.45 | G3: 26.57 | H3: -0.12 | I3: -0.4516 | J3: 656302.55 | K3: 1737617.8 | L3: 用户提供行情CSV | M3: 股票日行情 | N3: 45362 | O3: 2 | P3: 59 | Q3: -57 | R3: 事件前100个交易日
A4: 000063.SZ | B4: 45273 | C4: 26.45 | D4: 26.52 | E4: 25.88 | F4: 25.88 | G4: 26.45 | H4: -0.57 | I4: -2.155 | J4: 563549.26 | K4: 1475553.1 | L4: 用户提供行情CSV | M4: 股票日行情 | N4: 45362 | O4: 3 | P4: 59 | Q4: -56 | R4: 事件前100个交易日
A5: 000063.SZ | B5: 45274 | C5: 26.04 | D5: 27.27 | E5: 26.04 | F5: 26.35 | G5: 25.88 | H5: 0.47 | I5: 1.8161 | J5: 1281248.1 | K5: 3427086 | L5: 用户提供行情CSV | M5: 股票日行情 | N5: 45362 | O5: 4 | P5: 59 | Q5: -55 | R5: 事件前100个交易日
A6: 000063.SZ | B6: 45275 | C6: 26.46 | D6: 27.24 | E6: 26.12 | F6: 26.68 | G6: 26.35 | H6: 0.33 | I6: 1.2524 | J6: 1428091.4 | K6: 3825279.8 | L6: 用户提供行情CSV | M6: 股票日行情 | N6: 45362 | O6: 5 | P6: 59 | Q6: -54 | R6: 事件前100个交易日
A7: 000063.SZ | B7: 45278 | C7: 26.45 | D7: 26.54 | E7: 25.75 | F7: 25.97 | G7: 26.68 | H7: -0.71 | I7: -2.6612 | J7: 784957.34 | K7: 2052296.4 | L7: 用户提供行情CSV | M7: 股票日行情 | N7: 45362 | O7: 6 | P7: 59 | Q7: -53 | R7: 事件前100个交易日
A8: 000063.SZ | B8: 45279 | C8: 25.83 | D8: 26.24 | E8: 25.66 | F8: 25.94 | G8: 25.97 | H8: -0.03 | I8: -0.1155 | J8: 597918.92 | K8: 1549182.5 | L8: 用户提供行情CSV | M8: 股票日行情 | N8: 45362 | O8: 7 | P8: 59 | Q8: -52 | R8: 事件前100个交易日
A9: 000063.SZ | B9: 45280 | C9: 25.94 | D9: 26.01 | E9: 25.15 | F9: 25.16 | G9: 25.94 | H9: -0.78 | I9: -3.0069 | J9: 721276.72 | K9: 1832348.8 | L9: 用户提供行情CSV | M9: 股票日行情 | N9: 45362 | O9: 8 | P9: 59 | Q9: -51 | R9: 事件前100个交易日
A10: 000063.SZ | B10: 45281 | C10: 24.93 | D10: 25.74 | E10: 24.7 | F10: 25.57 | G10: 25.16 | H10: 0.41 | I10: 1.6296 | J10: 738459.37 | K10: 1861487.7 | L10: 用户提供行情CSV | M10: 股票日行情 | N10: 45362 | O10: 9 | P10: 59 | Q10: -50 | R10: 事件前100个交易日
A11: 000063.SZ | B11: 45282 | C11: 25.57 | D11: 25.95 | E11: 25.01 | F11: 25.17 | G11: 25.57 | H11: -0.4 | I11: -1.5643 | J11: 690324.53 | K11: 1758705 | L11: 用户提供行情CSV | M11: 股票日行情 | N11: 45362 | O11: 10 | P11: 59 | Q11: -49 | R11: 事件前100个交易日
A12: 000063.SZ | B12: 45285 | C12: 25.1 | D12: 25.66 | E12: 25.1 | F12: 25.32 | G12: 25.17 | H12: 0.15 | I12: 0.5959 | J12: 446303.98 | K12: 1133568.4 | L12: 用户提供行情CSV | M12: 股票日行情 | N12: 45362 | O12: 11 | P12: 59 | Q12: -48 | R12: 事件前100个交易日
A13: 000063.SZ | B13: 45286 | C13: 25.27 | D13: 25.32 | E13: 24.38 | F13: 24.64 | G13: 25.32 | H13: -0.68 | I13: -2.6856 | J13: 709431.56 | K13: 1753394.3 | L13: 用户提供行情CSV | M13: 股票日行情 | N13: 45362 | O13: 12 | P13: 59 | Q13: -47 | R13: 事件前100个交易日
... A64: 000063.SZ | B64: 45366 | C64: 28.65 | D64: 29.1 | E64: 28.22 | F64: 29 | G64: 28.8 | H64: 0.2 | I64: 0.6944 | J64: 1231825.3 | K64: 3531568.1 | L64: 用户提供行情CSV | M64: 股票日行情 | N64: 45362 | O64: 63 | P64: 59 | Q64: 4 | R64: 事件后5个交易日

Sheet 000925.SZ_元数据
A1: 字段 | B1: 内容
A2: 股票代码 | B2: 000925.SZ
A3: 事件名称 | B3: 众合科技： 关于公司算力战略合作框架协议的实施进展公告（三）
A4: 事件日期 | B4: 45302
A5: 数据来源 | B5: 用户提供行情CSV + 事件库1.csv
A6: 分类规则 | B6: 前100个交易日 / 事件当日 / 后5个交易日
A7: 事件ID | B7: 2
A8: 内容链接 | B8: https://www.cninfo.com.cn/new/disclosure/detail?orgId=gssz0000925&announcementId=1218845958&announcementTime=2024-01-11
A9: 事件来源 | B9: 巨潮资讯
A10: 事件类型 | B10: 公司行为
A11: 行业 | B11: 算力
A12: 有效交易日(T0) | B12: 45302
A13: 窗口覆盖说明 | B13: 前窗口覆盖 81/100 个交易日；后窗口覆盖 3/5 个交易日
A14: 说明 | B14: 若事件日期不是交易日，则 T0 取事件日期之后的首个交易日。

Sheet 000925.SZ_行情
A1: ts_code | B1: trade_date | C1: open | D1: high | E1: low | F1: close | G1: pre_close | H1: change | I1: pct_chg | J1: vol | K1: amount | L1: 数据来源 | M1: 数据分类 | N1: 事件日期 | O1: 交易日序号 | P1: 事件交易日序号 | Q1: 相对交易日 | R1: 窗口标签 | S1: 备注
A2: 000925.SZ | B2: 45180 | C2: 7.77 | D2: 8.24 | E2: 7.76 | F2: 7.96 | G2: 7.8 | H2: 0.16 | I2: 2.0513 | J2: 264059.71 | K2: 210320.7 | L2: 用户提供行情CSV | M2: 股票日行情 | N2: 45302 | O2: 1 | P2: 82 | Q2: -81 | R2: 事件前100个交易日
A3: 000925.SZ | B3: 45181 | C3: 7.99 | D3: 8.08 | E3: 7.91 | F3: 7.94 | G3: 7.96 | H3: -0.02 | I3: -0.2513 | J3: 195644.57 | K3: 156247.69 | L3: 用户提供行情CSV | M3: 股票日行情 | N3: 45302 | O3: 2 | P3: 82 | Q3: -80 | R3: 事件前100个交易日
A4: 000925.SZ | B4: 45182 | C4: 7.82 | D4: 7.89 | E4: 7.62 | F4: 7.68 | G4: 7.94 | H4: -0.26 | I4: -3.2746 | J4: 148305 | K4: 114804.33 | L4: 用户提供行情CSV | M4: 股票日行情 | N4: 45302 | O4: 3 | P4: 82 | Q4: -79 | R4: 事件前100个交易日
A5: 000925.SZ | B5: 45183 | C5: 7.68 | D5: 7.96 | E5: 7.58 | F5: 7.67 | G5: 7.68 | H5: -0.01 | I5: -0.1302 | J5: 109829 | K5: 84695.467 | L5: 用户提供行情CSV | M5: 股票日行情 | N5: 45302 | O5: 4 | P5: 82 | Q5: -78 | R5: 事件前100个交易日
A6: 000925.SZ | B6: 45184 | C6: 7.73 | D6: 7.73 | E6: 7.56 | F6: 7.61 | G6: 7.67 | H6: -0.06 | I6: -0.7823 | J6: 78608.8 | K6: 59930.15 | L6: 用户提供行情CSV | M6: 股票日行情 | N6: 45302 | O6: 5 | P6: 82 | Q6: -77 | R6: 事件前100个交易日
A7: 000925.SZ | B7: 45187 | C7: 7.57 | D7: 7.65 | E7: 7.5 | F7: 7.58 | G7: 7.61 | H7: -0.03 | I7: -0.3942 | J7: 53255.48 | K7: 40353.522 | L7: 用户提供行情CSV | M7: 股票日行情 | N7: 45302 | O7: 6 | P7: 82 | Q7: -76 | R7: 事件前100个交易日
A8: 000925.SZ | B8: 45188 | C8: 7.6 | D8: 7.6 | E8: 7.35 | F8: 7.36 | G8: 7.58 | H8: -0.22 | I8: -2.9024 | J8: 84276.2 | K8: 62510.257 | L8: 用户提供行情CSV | M8: 股票日行情 | N8: 45302 | O8: 7 | P8: 82 | Q8: -75 | R8: 事件前100个交易日
A9: 000925.SZ | B9: 45189 | C9: 7.4 | D9: 7.58 | E9: 7.33 | F9: 7.41 | G9: 7.36 | H9: 0.05 | I9: 0.6793 | J9: 67820.81 | K9: 50331.45 | L9: 用户提供行情CSV | M9: 股票日行情 | N9: 45302 | O9: 8 | P9: 82 | Q9: -74 | R9: 事件前100个交易日
A10: 000925.SZ | B10: 45190 | C10: 7.44 | D10: 8 | E10: 7.4 | F10: 7.64 | G10: 7.41 | H10: 0.23 | I10: 3.1039 | J10: 253779.46 | K10: 197763.75 | L10: 用户提供行情CSV | M10: 股票日行情 | N10: 45302 | O10: 9 | P10: 82 | Q10: -73 | R10: 事件前100个交易日
A11: 000925.SZ | B11: 45191 | C11: 7.59 | D11: 7.72 | E11: 7.38 | F11: 7.69 | G11: 7.64 | H11: 0.05 | I11: 0.6545 | J11: 169673.6 | K11: 127941.79 | L11: 用户提供行情CSV | M11: 股票日行情 | N11: 45302 | O11: 10 | P11: 82 | Q11: -72 | R11: 事件前100个交易日
A12: 000925.SZ | B12: 45194 | C12: 7.7 | D12: 7.82 | E12: 7.56 | F12: 7.62 | G12: 7.69 | H12: -0.07 | I12: -0.9103 | J12: 100928.4 | K12: 77395.309 | L12: 用户提供行情CSV | M12: 股票日行情 | N12: 45302 | O12: 11 | P12: 82 | Q12: -71 | R12: 事件前100个交易日
A13: 000925.SZ | B13: 45195 | C13: 7.62 | D13: 7.62 | E13: 7.49 | F13: 7.49 | G13: 7.62 | H13: -0.13 | I13: -1.706 | J13: 66175.8 | K13: 49785.519 | L13: 用户提供行情CSV | M13: 股票日行情 | N13: 45302 | O13: 12 | P13: 82 | Q13: -70 | R13: 事件前100个交易日
... A86: 000925.SZ | B86: 45307 | C86: 8.27 | D86: 8.3 | E86: 7.95 | F86: 8.04 | G86: 8.27 | H86: -0.23 | I86: -2.7811 | J86: 198869.02 | K86: 160071.59 | L86: 用户提供行情CSV | M86: 股票日行情 | N86: 45302 | O86: 85 | P86: 82 | Q86: 3 | R86: 事件后5个交易日

Sheet 002685.SZ_元数据
A1: 字段 | B1: 内容
A2: 股票代码 | B2: 002685.SZ
A3: 事件名称 | B3: 港机订单稳定向好，布局GPU打造新成长极
A4: 事件日期 | B4: 45907
A5: 数据来源 | B5: 用户提供行情CSV + 事件库1.csv
A6: 分类规则 | B6: 前100个交易日 / 事件当日 / 后5个交易日
A7: 事件ID | B7: 21
A8: 内容链接 | B8: http://data.eastmoney.com/report/zw_stock.jshtml?infocode=AP202509071739972457
A9: 事件来源 | B9: 东方财富
A10: 事件类型 | B10: 技术
A11: 行业 | B11: GPU
A12: 有效交易日(T0) | B12: 45908
A13: 窗口覆盖说明 | B13: 前窗口覆盖 65/100 个交易日；后窗口覆盖 4/5 个交易日
A14: 说明 | B14: 若事件日期不是交易日，则 T0 取事件日期之后的首个交易日。

Sheet 002685.SZ_行情
A1: ts_code | B1: trade_date | C1: open | D1: high | E1: low | F1: close | G1: pre_close | H1: change | I1: pct_chg | J1: vol | K1: amount | L1: 数据来源 | M1: 数据分类 | N1: 事件日期 | O1: 交易日序号 | P1: 事件交易日序号 | Q1: 相对交易日 | R1: 窗口标签 | S1: 备注
A2: 002685.SZ | B2: 45817 | C2: 7.26 | D2: 7.31 | E2: 6.91 | F2: 6.96 | G2: 7.26 | H2: -0.3 | I2: -4.1322 | J2: 856904.31 | K2: 602444.74 | L2: 用户提供行情CSV | M2: 股票日行情 | N2: 45907 | O2: 1 | P2: 66 | Q2: -65 | R2: 事件前100个交易日
A3: 002685.SZ | B3: 45818 | C3: 6.95 | D3: 6.95 | E3: 6.71 | F3: 6.79 | G3: 6.96 | H3: -0.17 | I3: -2.4425 | J3: 597267.8 | K3: 406651.31 | L3: 用户提供行情CSV | M3: 股票日行情 | N3: 45907 | O3: 2 | P3: 66 | Q3: -64 | R3: 事件前100个交易日
A4: 002685.SZ | B4: 45819 | C4: 6.79 | D4: 6.85 | E4: 6.74 | F4: 6.75 | G4: 6.79 | H4: -0.04 | I4: -0.5891 | J4: 288112.76 | K4: 195398.88 | L4: 用户提供行情CSV | M4: 股票日行情 | N4: 45907 | O4: 3 | P4: 66 | Q4: -63 | R4: 事件前100个交易日
A5: 002685.SZ | B5: 45820 | C5: 6.71 | D5: 6.78 | E5: 6.65 | F5: 6.7 | G5: 6.75 | H5: -0.05 | I5: -0.7407 | J5: 292918.2 | K5: 196362.24 | L5: 用户提供行情CSV | M5: 股票日行情 | N5: 45907 | O5: 4 | P5: 66 | Q5: -62 | R5: 事件前100个交易日
A6: 002685.SZ | B6: 45821 | C6: 6.71 | D6: 6.72 | E6: 6.52 | F6: 6.58 | G6: 6.7 | H6: -0.12 | I6: -1.791 | J6: 276312 | K6: 182096.01 | L6: 用户提供行情CSV | M6: 股票日行情 | N6: 45907 | O6: 5 | P6: 66 | Q6: -61 | R6: 事件前100个交易日
A7: 002685.SZ | B7: 45824 | C7: 6.59 | D7: 6.65 | E7: 6.55 | F7: 6.62 | G7: 6.58 | H7: 0.04 | I7: 0.6079 | J7: 187950.63 | K7: 124332.81 | L7: 用户提供行情CSV | M7: 股票日行情 | N7: 45907 | O7: 6 | P7: 66 | Q7: -60 | R7: 事件前100个交易日
A8: 002685.SZ | B8: 45825 | C8: 6.61 | D8: 6.76 | E8: 6.6 | F8: 6.66 | G8: 6.62 | H8: 0.04 | I8: 0.6042 | J8: 262872 | K8: 175575.27 | L8: 用户提供行情CSV | M8: 股票日行情 | N8: 45907 | O8: 7 | P8: 66 | Q8: -59 | R8: 事件前100个交易日
A9: 002685.SZ | B9: 45826 | C9: 6.66 | D9: 6.98 | E9: 6.63 | F9: 6.97 | G9: 6.66 | H9: 0.31 | I9: 4.6547 | J9: 719293.36 | K9: 493422.45 | L9: 用户提供行情CSV | M9: 股票日行情 | N9: 45907 | O9: 8 | P9: 66 | Q9: -58 | R9: 事件前100个交易日
A10: 002685.SZ | B10: 45827 | C10: 6.97 | D10: 7.28 | E10: 6.84 | F10: 7.09 | G10: 6.97 | H10: 0.12 | I10: 1.7217 | J10: 777669.35 | K10: 552469.39 | L10: 用户提供行情CSV | M10: 股票日行情 | N10: 45907 | O10: 9 | P10: 66 | Q10: -57 | R10: 事件前100个交易日
A11: 002685.SZ | B11: 45828 | C11: 7.1 | D11: 7.46 | E11: 6.88 | F11: 7.36 | G11: 7.09 | H11: 0.27 | I11: 3.8082 | J11: 870026.1 | K11: 627279.62 | L11: 用户提供行情CSV | M11: 股票日行情 | N11: 45907 | O11: 10 | P11: 66 | Q11: -56 | R11: 事件前100个交易日
A12: 002685.SZ | B12: 45831 | C12: 7.17 | D12: 7.54 | E12: 7.06 | F12: 7.34 | G12: 7.36 | H12: -0.02 | I12: -0.2717 | J12: 634537.13 | K12: 462274.28 | L12: 用户提供行情CSV | M12: 股票日行情 | N12: 45907 | O12: 11 | P12: 66 | Q12: -55 | R12: 事件前100个交易日
A13: 002685.SZ | B13: 45832 | C13: 7.27 | D13: 7.5 | E13: 7.24 | F13: 7.35 | G13: 7.34 | H13: 0.01 | I13: 0.1362 | J13: 636334.48 | K13: 470132.49 | L13: 用户提供行情CSV | M13: 股票日行情 | N13: 45907 | O13: 12 | P13: 66 | Q13: -54 | R13: 事件前100个交易日
... A66: 002685.SZ | B66: 45905 | C66: 8.07 | D66: 8.23 | E66: 7.99 | F66: 8.22 | G66: 8.02 | H66: 0.2 | I66: 2.4938 | J66: 436369.29 | K66: 355535.73 | L66: 用户提供行情CSV | M66: 股票日行情 | N66: 45907 | O66: 65 | P66: 66 | Q66: -1 | R66: 事件前100个交易日
A67: 002685.SZ | B67: 45908 | C67: 8.16 | D67: 8.27 | E67: 8.1 | F67: 8.17 | G67: 8.22 | H67: -0.05 | I67: -0.6083 | J67: 371436.44 | K67: 303769.35 | L67: 用户提供行情CSV | M67: 股票日行情 | N67: 45907 | O67: 66 | P67: 66 | Q67: 0 | R67: 事件当日 | S67: 事件日非交易日，T0顺延至下一交易日
A68: 002685.SZ | B68: 45909 | C68: 8.11 | D68: 8.24 | E68: 7.98 | F68: 8.09 | G68: 8.17 | H68: -0.08 | I68: -0.9792 | J68: 439571.93 | K68: 356143.45 | L68: 用户提供行情CSV | M68: 股票日行情 | N68: 45907 | O68: 67 | P68: 66 | Q68: 1 | R68: 事件后5个交易日
A69: 002685.SZ | B69: 45910 | C69: 8.18 | D69: 8.22 | E69: 8.1 | F69: 8.17 | G69: 8.09 | H69: 0.08 | I69: 0.9889 | J69: 352429.86 | K69: 287834.51 | L69: 用户提供行情CSV | M69: 股票日行情 | N69: 45907 | O69: 68 | P69: 66 | Q69: 2 | R69: 事件后5个交易日
A70: 002685.SZ | B70: 45911 | C70: 8.11 | D70: 8.49 | E70: 8.03 | F70: 8.36 | G70: 8.17 | H70: 0.19 | I70: 2.3256 | J70: 572186.63 | K70: 473499.79 | L70: 用户提供行情CSV | M70: 股票日行情 | N70: 45907 | O70: 69 | P70: 66 | Q70: 3 | R70: 事件后5个交易日
A71: 002685.SZ | B71: 45912 | C71: 8.28 | D71: 8.44 | E71: 8.19 | F71: 8.3 | G71: 8.36 | H71: -0.06 | I71: -0.7177 | J71: 487218.29 | K71: 405478.82 | L71: 用户提供行情CSV | M71: 股票日行情 | N71: 45907 | O71: 70 | P71: 66 | Q71: 4 | R71: 事件后5个交易日

Sheet 300054.SZ_元数据
A1: 字段 | B1: 内容
A2: 股票代码 | B2: 300054.SZ
A3: 事件名称 | B3: 鼎龙股份半导体材料营收同比增长，新品研发及导入进展顺利
A4: 事件日期 | B4: 45344
A5: 数据来源 | B5: 用户提供行情CSV + 事件库1.csv
A6: 分类规则 | B6: 前100个交易日 / 事件当日 / 后5个交易日
A7: 事件ID | B7: 42
A8: 内容链接 | B8: http://data.eastmoney.com/report/zw_stock.jshtml?infocode=AP202404221630960435
A9: 事件来源 | B9: 东方财富
A10: 事件类型 | B10: 技术
A11: 行业 | B11: 半导体
A12: 有效交易日(T0) | B12: 45344
A13: 窗口覆盖说明 | B13: 前窗口覆盖 59/100 个交易日；后窗口覆盖 3/5 个交易日
A14: 说明 | B14: 若事件日期不是交易日，则 T0 取事件日期之后的首个交易日。

Sheet 300054.SZ_行情
A1: ts_code | B1: trade_date | C1: open | D1: high | E1: low | F1: close | G1: pre_close | H1: change | I1: pct_chg | J1: vol | K1: amount | L1: 数据来源 | M1: 数据分类 | N1: 事件日期 | O1: 交易日序号 | P1: 事件交易日序号 | Q1: 相对交易日 | R1: 窗口标签 | S1: 备注
A2: 300054.SZ | B2: 45252 | C2: 24.33 | D2: 24.64 | E2: 24.12 | F2: 24.2 | G2: 24.42 | H2: -0.22 | I2: -0.9009 | J2: 54002.04 | K2: 131562.48 | L2: 用户提供行情CSV | M2: 股票日行情 | N2: 45344 | O2: 1 | P2: 60 | Q2: -59 | R2: 事件前100个交易日
A3: 300054.SZ | B3: 45253 | C3: 24.17 | D3: 24.76 | E3: 24.14 | F3: 24.54 | G3: 24.2 | H3: 0.34 | I3: 1.405 | J3: 56482.84 | K3: 138426.67 | L3: 用户提供行情CSV | M3: 股票日行情 | N3: 45344 | O3: 2 | P3: 60 | Q3: -58 | R3: 事件前100个交易日
A4: 300054.SZ | B4: 45254 | C4: 24.45 | D4: 24.62 | E4: 23.98 | F4: 24.1 | G4: 24.54 | H4: -0.44 | I4: -1.793 | J4: 54534.98 | K4: 131945.36 | L4: 用户提供行情CSV | M4: 股票日行情 | N4: 45344 | O4: 3 | P4: 60 | Q4: -57 | R4: 事件前100个交易日
A5: 300054.SZ | B5: 45257 | C5: 23.8 | D5: 24.68 | E5: 23.79 | F5: 24.55 | G5: 24.1 | H5: 0.45 | I5: 1.8672 | J5: 68307.9 | K5: 167069.21 | L5: 用户提供行情CSV | M5: 股票日行情 | N5: 45344 | O5: 4 | P5: 60 | Q5: -56 | R5: 事件前100个交易日
A6: 300054.SZ | B6: 45258 | C6: 24.47 | D6: 24.68 | E6: 24.33 | F6: 24.55 | G6: 24.55 | H6: 0 | I6: 0 | J6: 41877 | K6: 102517.69 | L6: 用户提供行情CSV | M6: 股票日行情 | N6: 45344 | O6: 5 | P6: 60 | Q6: -55 | R6: 事件前100个交易日
A7: 300054.SZ | B7: 45259 | C7: 24.55 | D7: 25.3 | E7: 24.55 | F7: 24.75 | G7: 24.55 | H7: 0.2 | I7: 0.8147 | J7: 83231.82 | K7: 207618.33 | L7: 用户提供行情CSV | M7: 股票日行情 | N7: 45344 | O7: 6 | P7: 60 | Q7: -54 | R7: 事件前100个交易日
A8: 300054.SZ | B8: 45260 | C8: 24.55 | D8: 24.72 | E8: 24.16 | F8: 24.49 | G8: 24.75 | H8: -0.26 | I8: -1.0505 | J8: 46646.51 | K8: 113603.35 | L8: 用户提供行情CSV | M8: 股票日行情 | N8: 45344 | O8: 7 | P8: 60 | Q8: -53 | R8: 事件前100个交易日
A9: 300054.SZ | B9: 45261 | C9: 24.55 | D9: 24.71 | E9: 24.07 | F9: 24.7 | G9: 24.49 | H9: 0.21 | I9: 0.8575 | J9: 45043.22 | K9: 109837.99 | L9: 用户提供行情CSV | M9: 股票日行情 | N9: 45344 | O9: 8 | P9: 60 | Q9: -52 | R9: 事件前100个交易日
A10: 300054.SZ | B10: 45264 | C10: 24.7 | D10: 24.85 | E10: 24.1 | F10: 24.23 | G10: 24.7 | H10: -0.47 | I10: -1.9028 | J10: 44881.15 | K10: 109841.26 | L10: 用户提供行情CSV | M10: 股票日行情 | N10: 45344 | O10: 9 | P10: 60 | Q10: -51 | R10: 事件前100个交易日
A11: 300054.SZ | B11: 45265 | C11: 24.2 | D11: 24.2 | E11: 23.81 | F11: 23.98 | G11: 24.23 | H11: -0.25 | I11: -1.0318 | J11: 42215 | K11: 101088.26 | L11: 用户提供行情CSV | M11: 股票日行情 | N11: 45344 | O11: 10 | P11: 60 | Q11: -50 | R11: 事件前100个交易日
A12: 300054.SZ | B12: 45266 | C12: 23.81 | D12: 24.1 | E12: 23.67 | F12: 23.9 | G12: 23.98 | H12: -0.08 | I12: -0.3336 | J12: 36133.04 | K12: 86453.783 | L12: 用户提供行情CSV | M12: 股票日行情 | N12: 45344 | O12: 11 | P12: 60 | Q12: -49 | R12: 事件前100个交易日
A13: 300054.SZ | B13: 45267 | C13: 23.83 | D13: 23.96 | E13: 23.44 | F13: 23.57 | G13: 23.9 | H13: -0.33 | I13: -1.3808 | J13: 37577.81 | K13: 88690.237 | L13: 用户提供行情CSV | M13: 股票日行情 | N13: 45344 | O13: 12 | P13: 60 | Q13: -48 | R13: 事件前100个交易日
... A64: 300054.SZ | B64: 45349 | C64: 20.01 | D64: 20.69 | E64: 19.82 | F64: 20.68 | G64: 20.01 | H64: 0.67 | I64: 3.3483 | J64: 94253.62 | K64: 191403.35 | L64: 用户提供行情CSV | M64: 股票日行情 | N64: 45344 | O64: 63 | P64: 60 | Q64: 3 | R64: 事件后5个交易日

Sheet 300474.SZ_元数据
A1: 字段 | B1: 内容
A2: 股票代码 | B2: 300474.SZ
A3: 事件名称 | B3: 显卡、通用GPU双线布局，管理变革推动创新
A4: 事件日期 | B4: 45876
A5: 数据来源 | B5: 事件库1.csv + 股票日行情CSV
A6: 分类规则 | B6: 前100个交易日 / 后5个交易日
A7: 说明 | B7: 使用事件库匹配事件，并按事件日期定位 T0；若事件日非交易日，则顺延到下一交易日。
A8: 原始事件日期 | B8: 45876
A9: 事件ID | B9: 22
A10: 事件类型 | B10: 技术
A11: 行业 | B11: GPU
A12: 内容链接 | B12: http://data.eastmoney.com/report/zw_stock.jshtml?infocode=AP202508071723199368
A13: 对齐说明 | B13: 已匹配

Sheet 300474.SZ_行情
A1: 代码 | B1: 日期 | C1: 开盘价 | D1: 最高价 | E1: 最低价 | F1: 收盘价 | G1: 昨日收盘价 | H1: 变化量 | I1: 涨跌幅 | J1: 成交量 | K1: 金额 | L1: 数据来源 | M1: 数据分类 | N1: 事件日期 | O1: 交易日序号 | P1: 事件交易日序号 | Q1: 相对交易日 | R1: 窗口标签 | S1: 备注
A2: 300474.SZ | B2: 45784 | C2: 70.92 | D2: 71.27 | E2: 67.51 | F2: 68.2 | G2: 70.62 | H2: -2.42 | I2: -3.4268 | J2: 243544.18 | K2: 1678559.4 | L2: ='300474.SZ_元数据'!$B$5 -> 事件库1.csv + 股票日行情CSV | M2: 股票日行情 | N2: ='300474.SZ_元数据'!$B$4 -> 45876 | O2: =ROW()-1 -> 1 | P2: =IFERROR(MATCH($N2,$B$2:$B$70,0),"") -> 66 | Q2: =IF(OR($P2="",$O2=""),"",$O2-$P2) -> -65 | R2: =IF($Q2="","",IF(AND($Q2>=-100,$Q2<=-1),"事件前100个交易日",IF(AND($Q2>=1,$Q2<=5),"事件后5个交易日",IF($Q2=0,"事件当日","其他区间")))) -> 事件前100个交易日
A3: 300474.SZ | B3: 45785 | C3: 68.2 | D3: 70.86 | E3: 67.42 | F3: 70.57 | G3: 68.2 | H3: 2.37 | I3: 3.4751 | J3: 194454.56 | K3: 1354143.3 | L3: ='300474.SZ_元数据'!$B$5 -> 事件库1.csv + 股票日行情CSV | M3: 股票日行情 | N3: ='300474.SZ_元数据'!$B$4 -> 45876 | O3: =ROW()-1 -> 2 | P3: =IFERROR(MATCH($N3,$B$2:$B$70,0),"") -> 66 | Q3: =IF(OR($P3="",$O3=""),"",$O3-$P3) -> -64 | R3: =IF($Q3="","",IF(AND($Q3>=-100,$Q3<=-1),"事件前100个交易日",IF(AND($Q3>=1,$Q3<=5),"事件后5个交易日",IF($Q3=0,"事件当日","其他区间")))) -> 事件前100个交易日
A4: 300474.SZ | B4: 45786 | C4: 71 | D4: 71.92 | E4: 68.88 | F4: 69.1 | G4: 70.57 | H4: -1.47 | I4: -2.083 | J4: 144415.06 | K4: 1009844.4 | L4: ='300474.SZ_元数据'!$B$5 -> 事件库1.csv + 股票日行情CSV | M4: 股票日行情 | N4: ='300474.SZ_元数据'!$B$4 -> 45876 | O4: =ROW()-1 -> 3 | P4: =IFERROR(MATCH($N4,$B$2:$B$70,0),"") -> 66 | Q4: =IF(OR($P4="",$O4=""),"",$O4-$P4) -> -63 | R4: =IF($Q4="","",IF(AND($Q4>=-100,$Q4<=-1),"事件前100个交易日",IF(AND($Q4>=1,$Q4<=5),"事件后5个交易日",IF($Q4=0,"事件当日","其他区间")))) -> 事件前100个交易日
A5: 300474.SZ | B5: 45789 | C5: 70.2 | D5: 74 | E5: 69.65 | F5: 72.53 | G5: 69.1 | H5: 3.43 | I5: 4.9638 | J5: 231225.13 | K5: 1667221.3 | L5: ='300474.SZ_元数据'!$B$5 -> 事件库1.csv + 股票日行情CSV | M5: 股票日行情 | N5: ='300474.SZ_元数据'!$B$4 -> 45876 | O5: =ROW()-1 -> 4 | P5: =IFERROR(MATCH($N5,$B$2:$B$70,0),"") -> 66 | Q5: =IF(OR($P5="",$O5=""),"",$O5-$P5) -> -62 | R5: =IF($Q5="","",IF(AND($Q5>=-100,$Q5<=-1),"事件前100个交易日",IF(AND($Q5>=1,$Q5<=5),"事件后5个交易日",IF($Q5=0,"事件当日","其他区间")))) -> 事件前100个交易日
A6: 300474.SZ | B6: 45790 | C6: 73.02 | D6: 73.02 | E6: 70.23 | F6: 70.59 | G6: 72.53 | H6: -1.94 | I6: -2.6748 | J6: 174108.19 | K6: 1240781 | L6: ='300474.SZ_元数据'!$B$5 -> 事件库1.csv + 股票日行情CSV | M6: 股票日行情 | N6: ='300474.SZ_元数据'!$B$4 -> 45876 | O6: =ROW()-1 -> 5 | P6: =IFERROR(MATCH($N6,$B$2:$B$70,0),"") -> 66 | Q6: =IF(OR($P6="",$O6=""),"",$O6-$P6) -> -61 | R6: =IF($Q6="","",IF(AND($Q6>=-100,$Q6<=-1),"事件前100个交易日",IF(AND($Q6>=1,$Q6<=5),"事件后5个交易日",IF($Q6=0,"事件当日","其他区间")))) -> 事件前100个交易日
A7: 300474.SZ | B7: 45791 | C7: 70.7 | D7: 71.2 | E7: 69.41 | F7: 70.2 | G7: 70.59 | H7: -0.39 | I7: -0.5525 | J7: 127673.87 | K7: 895468.45 | L7: ='300474.SZ_元数据'!$B$5 -> 事件库1.csv + 股票日行情CSV | M7: 股票日行情 | N7: ='300474.SZ_元数据'!$B$4 -> 45876 | O7: =ROW()-1 -> 6 | P7: =IFERROR(MATCH($N7,$B$2:$B$70,0),"") -> 66 | Q7: =IF(OR($P7="",$O7=""),"",$O7-$P7) -> -60 | R7: =IF($Q7="","",IF(AND($Q7>=-100,$Q7<=-1),"事件前100个交易日",IF(AND($Q7>=1,$Q7<=5),"事件后5个交易日",IF($Q7=0,"事件当日","其他区间")))) -> 事件前100个交易日
A8: 300474.SZ | B8: 45792 | C8: 70.2 | D8: 70.2 | E8: 67.8 | F8: 67.8 | G8: 70.2 | H8: -2.4 | I8: -3.4188 | J8: 117503.9 | K8: 803715.93 | L8: ='300474.SZ_元数据'!$B$5 -> 事件库1.csv + 股票日行情CSV | M8: 股票日行情 | N8: ='300474.SZ_元数据'!$B$4 -> 45876 | O8: =ROW()-1 -> 7 | P8: =IFERROR(MATCH($N8,$B$2:$B$70,0),"") -> 66 | Q8: =IF(OR($P8="",$O8=""),"",$O8-$P8) -> -59 | R8: =IF($Q8="","",IF(AND($Q8>=-100,$Q8<=-1),"事件前100个交易日",IF(AND($Q8>=1,$Q8<=5),"事件后5个交易日",IF($Q8=0,"事件当日","其他区间")))) -> 事件前100个交易日
A9: 300474.SZ | B9: 45793 | C9: 67.41 | D9: 68.06 | E9: 67.21 | F9: 67.51 | G9: 67.8 | H9: -0.29 | I9: -0.4277 | J9: 67453.71 | K9: 456468.84 | L9: ='300474.SZ_元数据'!$B$5 -> 事件库1.csv + 股票日行情CSV | M9: 股票日行情 | N9: ='300474.SZ_元数据'!$B$4 -> 45876 | O9: =ROW()-1 -> 8 | P9: =IFERROR(MATCH($N9,$B$2:$B$70,0),"") -> 66 | Q9: =IF(OR($P9="",$O9=""),"",$O9-$P9) -> -58 | R9: =IF($Q9="","",IF(AND($Q9>=-100,$Q9<=-1),"事件前100个交易日",IF(AND($Q9>=1,$Q9<=5),"事件后5个交易日",IF($Q9=0,"事件当日","其他区间")))) -> 事件前100个交易日
A10: 300474.SZ | B10: 45796 | C10: 67.78 | D10: 68.18 | E10: 66.84 | F10: 68 | G10: 67.51 | H10: 0.49 | I10: 0.7258 | J10: 76675.83 | K10: 519214.91 | L10: ='300474.SZ_元数据'!$B$5 -> 事件库1.csv + 股票日行情CSV | M10: 股票日行情 | N10: ='300474.SZ_元数据'!$B$4 -> 45876 | O10: =ROW()-1 -> 9 | P10: =IFERROR(MATCH($N10,$B$2:$B$70,0),"") -> 66 | Q10: =IF(OR($P10="",$O10=""),"",$O10-$P10) -> -57 | R10: =IF($Q10="","",IF(AND($Q10>=-100,$Q10<=-1),"事件前100个交易日",IF(AND($Q10>=1,$Q10<=5),"事件后5个交易日",IF($Q10=0,"事件当日","其他区间")))) -> 事件前100个交易日
A11: 300474.SZ | B11: 45797 | C11: 67.8 | D11: 68.13 | E11: 67.3 | F11: 67.73 | G11: 68 | H11: -0.27 | I11: -0.3971 | J11: 70379.34 | K11: 476461.35 | L11: ='300474.SZ_元数据'!$B$5 -> 事件库1.csv + 股票日行情CSV | M11: 股票日行情 | N11: ='300474.SZ_元数据'!$B$4 -> 45876 | O11: =ROW()-1 -> 10 | P11: =IFERROR(MATCH($N11,$B$2:$B$70,0),"") -> 66 | Q11: =IF(OR($P11="",$O11=""),"",$O11-$P11) -> -56 | R11: =IF($Q11="","",IF(AND($Q11>=-100,$Q11<=-1),"事件前100个交易日",IF(AND($Q11>=1,$Q11<=5),"事件后5个交易日",IF($Q11=0,"事件当日","其他区间")))) -> 事件前100个交易日
A12: 300474.SZ | B12: 45798 | C12: 67.61 | D12: 67.87 | E12: 67 | F12: 67.06 | G12: 67.73 | H12: -0.67 | I12: -0.9892 | J12: 67646.26 | K12: 455340.74 | L12: ='300474.SZ_元数据'!$B$5 -> 事件库1.csv + 股票日行情CSV | M12: 股票日行情 | N12: ='300474.SZ_元数据'!$B$4 -> 45876 | O12: =ROW()-1 -> 11 | P12: =IFERROR(MATCH($N12,$B$2:$B$70,0),"") -> 66 | Q12: =IF(OR($P12="",$O12=""),"",$O12-$P12) -> -55 | R12: =IF($Q12="","",IF(AND($Q12>=-100,$Q12<=-1),"事件前100个交易日",IF(AND($Q12>=1,$Q12<=5),"事件后5个交易日",IF($Q12=0,"事件当日","其他区间")))) -> 事件前100个交易日
A13: 300474.SZ | B13: 45799 | C13: 66.9 | D13: 67.8 | E13: 66.66 | F13: 66.71 | G13: 67.06 | H13: -0.35 | I13: -0.5219 | J13: 63228.07 | K13: 424528.16 | L13: ='300474.SZ_元数据'!$B$5 -> 事件库1.csv + 股票日行情CSV | M13: 股票日行情 | N13: ='300474.SZ_元数据'!$B$4 -> 45876 | O13: =ROW()-1 -> 12 | P13: =IFERROR(MATCH($N13,$B$2:$B$70,0),"") -> 66 | Q13: =IF(OR($P13="",$O13=""),"",$O13-$P13) -> -54 | R13: =IF($Q13="","",IF(AND($Q13>=-100,$Q13<=-1),"事件前100个交易日",IF(AND($Q13>=1,$Q13<=5),"事件后5个交易日",IF($Q13=0,"事件当日","其他区间")))) -> 事件前100个交易日
... A66: 300474.SZ | B66: 45875 | C66: 83.1 | D66: 84.76 | E66: 82.55 | F66: 83.97 | G66: 84.75 | H66: -0.78 | I66: -0.9204 | J66: 215309.99 | K66: 1799891.1 | L66: ='300474.SZ_元数据'!$B$5 -> 事件库1.csv + 股票日行情CSV | M66: 股票日行情 | N66: ='300474.SZ_元数据'!$B$4 -> 45876 | O66: =ROW()-1 -> 65 | P66: =IFERROR(MATCH($N66,$B$2:$B$70,0),"") -> 66 | Q66: =IF(OR($P66="",$O66=""),"",$O66-$P66) -> -1 | R66: =IF($Q66="","",IF(AND($Q66>=-100,$Q66<=-1),"事件前100个交易日",IF(AND($Q66>=1,$Q66<=5),"事件后5个交易日",IF($Q66=0,"事件当日","其他区间")))) -> 事件前100个交易日
A67: 300474.SZ | B67: 45876 | C67: 84 | D67: 87.44 | E67: 83.02 | F67: 84.12 | G67: 83.97 | H67: 0.15 | I67: 0.1786 | J67: 275588.72 | K67: 2345494.2 | L67: ='300474.SZ_元数据'!$B$5 -> 事件库1.csv + 股票日行情CSV | M67: 股票日行情 | N67: ='300474.SZ_元数据'!$B$4 -> 45876 | O67: =ROW()-1 -> 66 | P67: =IFERROR(MATCH($N67,$B$2:$B$70,0),"") -> 66 | Q67: =IF(OR($P67="",$O67=""),"",$O67-$P67) -> 0 | R67: =IF($Q67="","",IF(AND($Q67>=-100,$Q67<=-1),"事件前100个交易日",IF(AND($Q67>=1,$Q67<=5),"事件后5个交易日",IF($Q67=0,"事件当日","其他区间")))) -> 事件当日 | S67: 原始事件日期非交易日，T0顺延至2025-08-07；事件前仅有65个交易日；事件后仅有3个交易日
A68: 300474.SZ | B68: 45877 | C68: 83.51 | D68: 83.89 | E68: 81.28 | F68: 82.2 | G68: 84.12 | H68: -1.92 | I68: -2.2825 | J68: 201460.32 | K68: 1656443.7 | L68: ='300474.SZ_元数据'!$B$5 -> 事件库1.csv + 股票日行情CSV | M68: 股票日行情 | N68: ='300474.SZ_元数据'!$B$4 -> 45876 | O68: =ROW()-1 -> 67 | P68: =IFERROR(MATCH($N68,$B$2:$B$70,0),"") -> 66 | Q68: =IF(OR($P68="",$O68=""),"",$O68-$P68) -> 1 | R68: =IF($Q68="","",IF(AND($Q68>=-100,$Q68<=-1),"事件前100个交易日",IF(AND($Q68>=1,$Q68<=5),"事件后5个交易日",IF($Q68=0,"事件当日","其他区间")))) -> 事件后5个交易日
A69: 300474.SZ | B69: 45880 | C69: 81.51 | D69: 84.86 | E69: 81.51 | F69: 83.9 | G69: 82.2 | H69: 1.7 | I69: 2.0681 | J69: 158830.23 | K69: 1320713 | L69: ='300474.SZ_元数据'!$B$5 -> 事件库1.csv + 股票日行情CSV | M69: 股票日行情 | N69: ='300474.SZ_元数据'!$B$4 -> 45876 | O69: =ROW()-1 -> 68 | P69: =IFERROR(MATCH($N69,$B$2:$B$70,0),"") -> 66 | Q69: =IF(OR($P69="",$O69=""),"",$O69-$P69) -> 2 | R69: =IF($Q69="","",IF(AND($Q69>=-100,$Q69<=-1),"事件前100个交易日",IF(AND($Q69>=1,$Q69<=5),"事件后5个交易日",IF($Q69=0,"事件当日","其他区间")))) -> 事件后5个交易日
A70: 300474.SZ | B70: 45881 | C70: 83.66 | D70: 86.12 | E70: 80.33 | F70: 85.22 | G70: 83.9 | H70: 1.32 | I70: 1.5733 | J70: 292933.69 | K70: 2452614.7 | L70: ='300474.SZ_元数据'!$B$5 -> 事件库1.csv + 股票日行情CSV | M70: 股票日行情 | N70: ='300474.SZ_元数据'!$B$4 -> 45876 | O70: =ROW()-1 -> 69 | P70: =IFERROR(MATCH($N70,$B$2:$B$70,0),"") -> 66 | Q70: =IF(OR($P70="",$O70=""),"",$O70-$P70) -> 3 | R70: =IF($Q70="","",IF(AND($Q70>=-100,$Q70<=-1),"事件前100个交易日",IF(AND($Q70>=1,$Q70<=5),"事件后5个交易日",IF($Q70=0,"事件当日","其他区间")))) -> 事件后5个交易日

Sheet 300496.SZ_元数据
A1: 字段 | B1: 内容
A2: 股票代码 | B2: 300496.SZ
A3: 事件名称 | B3: 智能汽车保持高增，大模型+边缘计算彰显长期价值
A4: 事件日期 | B4: 45159
A5: 数据来源 | B5: 事件库1.csv + 股票日行情CSV
A6: 分类规则 | B6: 前100个交易日 / 后5个交易日
A7: 说明 | B7: 使用事件库匹配事件，并按事件日期定位 T0；若事件日非交易日，则顺延到下一交易日。
A8: 原始事件日期 | B8: 45159
A9: 事件ID | B9: 35
A10: 事件类型 | B10: 技术
A11: 行业 | B11: 边缘计算
A12: 内容链接 | B12: http://data.eastmoney.com/report/zw_stock.jshtml?infocode=AP202308201595380625
A13: 对齐说明 | B13: 已匹配

Sheet 300496.SZ_行情
A1: 代码 | B1: 日期 | C1: 开盘价 | D1: 最高价 | E1: 最低价 | F1: 收盘价 | G1: 昨日收盘价 | H1: 变化量 | I1: 涨跌幅 | J1: 成交量 | K1: 金额 | L1: 数据来源 | M1: 数据分类 | N1: 事件日期 | O1: 交易日序号 | P1: 事件交易日序号 | Q1: 相对交易日 | R1: 窗口标签 | S1: 备注
A2: 300496.SZ | B2: 45068 | C2: 90.2 | D2: 90.58 | E2: 87.45 | F2: 88.18 | G2: 89.97 | H2: -1.79 | I2: -1.9896 | J2: 69551.14 | K2: 615237.41 | L2: ='300496.SZ_元数据'!$B$5 -> 事件库1.csv + 股票日行情CSV | M2: 股票日行情 | N2: ='300496.SZ_元数据'!$B$4 -> 45159 | O2: =ROW()-1 -> 1 | P2: =IFERROR(MATCH($N2,$B$2:$B$69,0),"") -> 64 | Q2: =IF(OR($P2="",$O2=""),"",$O2-$P2) -> -63 | R2: =IF($Q2="","",IF(AND($Q2>=-100,$Q2<=-1),"事件前100个交易日",IF(AND($Q2>=1,$Q2<=5),"事件后5个交易日",IF($Q2=0,"事件当日","其他区间")))) -> 事件前100个交易日
A3: 300496.SZ | B3: 45069 | C3: 88.01 | D3: 88.17 | E3: 84.12 | F3: 84.17 | G3: 88.18 | H3: -4.01 | I3: -4.5475 | J3: 104290.34 | K3: 892746.89 | L3: ='300496.SZ_元数据'!$B$5 -> 事件库1.csv + 股票日行情CSV | M3: 股票日行情 | N3: ='300496.SZ_元数据'!$B$4 -> 45159 | O3: =ROW()-1 -> 2 | P3: =IFERROR(MATCH($N3,$B$2:$B$69,0),"") -> 64 | Q3: =IF(OR($P3="",$O3=""),"",$O3-$P3) -> -62 | R3: =IF($Q3="","",IF(AND($Q3>=-100,$Q3<=-1),"事件前100个交易日",IF(AND($Q3>=1,$Q3<=5),"事件后5个交易日",IF($Q3=0,"事件当日","其他区间")))) -> 事件前100个交易日
A4: 300496.SZ | B4: 45070 | C4: 83.97 | D4: 85.47 | E4: 83.6 | F4: 84.1 | G4: 84.17 | H4: -0.07 | I4: -0.0832 | J4: 61353.96 | K4: 518683.89 | L4: ='300496.SZ_元数据'!$B$5 -> 事件库1.csv + 股票日行情CSV | M4: 股票日行情 | N4: ='300496.SZ_元数据'!$B$4 -> 45159 | O4: =ROW()-1 -> 3 | P4: =IFERROR(MATCH($N4,$B$2:$B$69,0),"") -> 64 | Q4: =IF(OR($P4="",$O4=""),"",$O4-$P4) -> -61 | R4: =IF($Q4="","",IF(AND($Q4>=-100,$Q4<=-1),"事件前100个交易日",IF(AND($Q4>=1,$Q4<=5),"事件后5个交易日",IF($Q4=0,"事件当日","其他区间")))) -> 事件前100个交易日
A5: 300496.SZ | B5: 45071 | C5: 85 | D5: 85.7 | E5: 82.4 | F5: 83.49 | G5: 84.1 | H5: -0.61 | I5: -0.7253 | J5: 58980.94 | K5: 493956 | L5: ='300496.SZ_元数据'!$B$5 -> 事件库1.csv + 股票日行情CSV | M5: 股票日行情 | N5: ='300496.SZ_元数据'!$B$4 -> 45159 | O5: =ROW()-1 -> 4 | P5: =IFERROR(MATCH($N5,$B$2:$B$69,0),"") -> 64 | Q5: =IF(OR($P5="",$O5=""),"",$O5-$P5) -> -60 | R5: =IF($Q5="","",IF(AND($Q5>=-100,$Q5<=-1),"事件前100个交易日",IF(AND($Q5>=1,$Q5<=5),"事件后5个交易日",IF($Q5=0,"事件当日","其他区间")))) -> 事件前100个交易日
A6: 300496.SZ | B6: 45072 | C6: 83.81 | D6: 83.93 | E6: 82.22 | F6: 83.45 | G6: 83.49 | H6: -0.04 | I6: -0.0479 | J6: 49244.53 | K6: 408992.13 | L6: ='300496.SZ_元数据'!$B$5 -> 事件库1.csv + 股票日行情CSV | M6: 股票日行情 | N6: ='300496.SZ_元数据'!$B$4 -> 45159 | O6: =ROW()-1 -> 5 | P6: =IFERROR(MATCH($N6,$B$2:$B$69,0),"") -> 64 | Q6: =IF(OR($P6="",$O6=""),"",$O6-$P6) -> -59 | R6: =IF($Q6="","",IF(AND($Q6>=-100,$Q6<=-1),"事件前100个交易日",IF(AND($Q6>=1,$Q6<=5),"事件后5个交易日",IF($Q6=0,"事件当日","其他区间")))) -> 事件前100个交易日
A7: 300496.SZ | B7: 45075 | C7: 85.46 | D7: 95.89 | E7: 85.39 | F7: 92.28 | G7: 83.45 | H7: 8.83 | I7: 10.5812 | J7: 251089.21 | K7: 2282135.6 | L7: ='300496.SZ_元数据'!$B$5 -> 事件库1.csv + 股票日行情CSV | M7: 股票日行情 | N7: ='300496.SZ_元数据'!$B$4 -> 45159 | O7: =ROW()-1 -> 6 | P7: =IFERROR(MATCH($N7,$B$2:$B$69,0),"") -> 64 | Q7: =IF(OR($P7="",$O7=""),"",$O7-$P7) -> -58 | R7: =IF($Q7="","",IF(AND($Q7>=-100,$Q7<=-1),"事件前100个交易日",IF(AND($Q7>=1,$Q7<=5),"事件后5个交易日",IF($Q7=0,"事件当日","其他区间")))) -> 事件前100个交易日
A8: 300496.SZ | B8: 45076 | C8: 91 | D8: 91.63 | E8: 89 | F8: 91.48 | G8: 92.28 | H8: -0.8 | I8: -0.8669 | J8: 137877.49 | K8: 1244018.6 | L8: ='300496.SZ_元数据'!$B$5 -> 事件库1.csv + 股票日行情CSV | M8: 股票日行情 | N8: ='300496.SZ_元数据'!$B$4 -> 45159 | O8: =ROW()-1 -> 7 | P8: =IFERROR(MATCH($N8,$B$2:$B$69,0),"") -> 64 | Q8: =IF(OR($P8="",$O8=""),"",$O8-$P8) -> -57 | R8: =IF($Q8="","",IF(AND($Q8>=-100,$Q8<=-1),"事件前100个交易日",IF(AND($Q8>=1,$Q8<=5),"事件后5个交易日",IF($Q8=0,"事件当日","其他区间")))) -> 事件前100个交易日
A9: 300496.SZ | B9: 45077 | C9: 95.59 | D9: 98.9 | E9: 95.59 | F9: 97.8 | G9: 91.48 | H9: 6.32 | I9: 6.9086 | J9: 258506.08 | K9: 2510750.9 | L9: ='300496.SZ_元数据'!$B$5 -> 事件库1.csv + 股票日行情CSV | M9: 股票日行情 | N9: ='300496.SZ_元数据'!$B$4 -> 45159 | O9: =ROW()-1 -> 8 | P9: =IFERROR(MATCH($N9,$B$2:$B$69,0),"") -> 64 | Q9: =IF(OR($P9="",$O9=""),"",$O9-$P9) -> -56 | R9: =IF($Q9="","",IF(AND($Q9>=-100,$Q9<=-1),"事件前100个交易日",IF(AND($Q9>=1,$Q9<=5),"事件后5个交易日",IF($Q9=0,"事件当日","其他区间")))) -> 事件前100个交易日
A10: 300496.SZ | B10: 45078 | C10: 95 | D10: 100.25 | E10: 94.72 | F10: 99.62 | G10: 97.8 | H10: 1.82 | I10: 1.8609 | J10: 212127.97 | K10: 2087758.7 | L10: ='300496.SZ_元数据'!$B$5 -> 事件库1.csv + 股票日行情CSV | M10: 股票日行情 | N10: ='300496.SZ_元数据'!$B$4 -> 45159 | O10: =ROW()-1 -> 9 | P10: =IFERROR(MATCH($N10,$B$2:$B$69,0),"") -> 64 | Q10: =IF(OR($P10="",$O10=""),"",$O10-$P10) -> -55 | R10: =IF($Q10="","",IF(AND($Q10>=-100,$Q10<=-1),"事件前100个交易日",IF(AND($Q10>=1,$Q10<=5),"事件后5个交易日",IF($Q10=0,"事件当日","其他区间")))) -> 事件前100个交易日
A11: 300496.SZ | B11: 45079 | C11: 100 | D11: 105.39 | E11: 99.62 | F11: 100.7 | G11: 99.62 | H11: 1.08 | I11: 1.0841 | J11: 216975.96 | K11: 2212574.5 | L11: ='300496.SZ_元数据'!$B$5 -> 事件库1.csv + 股票日行情CSV | M11: 股票日行情 | N11: ='300496.SZ_元数据'!$B$4 -> 45159 | O11: =ROW()-1 -> 10 | P11: =IFERROR(MATCH($N11,$B$2:$B$69,0),"") -> 64 | Q11: =IF(OR($P11="",$O11=""),"",$O11-$P11) -> -54 | R11: =IF($Q11="","",IF(AND($Q11>=-100,$Q11<=-1),"事件前100个交易日",IF(AND($Q11>=1,$Q11<=5),"事件后5个交易日",IF($Q11=0,"事件当日","其他区间")))) -> 事件前100个交易日
A12: 300496.SZ | B12: 45082 | C12: 99.5 | D12: 102.35 | E12: 98.94 | F12: 99.77 | G12: 100.7 | H12: -0.93 | I12: -0.9235 | J12: 122011.74 | K12: 1226211.8 | L12: ='300496.SZ_元数据'!$B$5 -> 事件库1.csv + 股票日行情CSV | M12: 股票日行情 | N12: ='300496.SZ_元数据'!$B$4 -> 45159 | O12: =ROW()-1 -> 11 | P12: =IFERROR(MATCH($N12,$B$2:$B$69,0),"") -> 64 | Q12: =IF(OR($P12="",$O12=""),"",$O12-$P12) -> -53 | R12: =IF($Q12="","",IF(AND($Q12>=-100,$Q12<=-1),"事件前100个交易日",IF(AND($Q12>=1,$Q12<=5),"事件后5个交易日",IF($Q12=0,"事件当日","其他区间")))) -> 事件前100个交易日
A13: 300496.SZ | B13: 45083 | C13: 99.28 | D13: 99.85 | E13: 93.88 | F13: 94.13 | G13: 99.77 | H13: -5.64 | I13: -5.653 | J13: 157192.54 | K13: 1509341.4 | L13: ='300496.SZ_元数据'!$B$5 -> 事件库1.csv + 股票日行情CSV | M13: 股票日行情 | N13: ='300496.SZ_元数据'!$B$4 -> 45159 | O13: =ROW()-1 -> 12 | P13: =IFERROR(MATCH($N13,$B$2:$B$69,0),"") -> 64 | Q13: =IF(OR($P13="",$O13=""),"",$O13-$P13) -> -52 | R13: =IF($Q13="","",IF(AND($Q13>=-100,$Q13<=-1),"事件前100个交易日",IF(AND($Q13>=1,$Q13<=5),"事件后5个交易日",IF($Q13=0,"事件当日","其他区间")))) -> 事件前100个交易日
... A64: 300496.SZ | B64: 45156 | C64: 82.83 | D64: 83.01 | E64: 80.42 | F64: 80.42 | G64: 82.74 | H64: -2.32 | I64: -2.804 | J64: 58783.74 | K64: 478159.25 | L64: ='300496.SZ_元数据'!$B$5 -> 事件库1.csv + 股票日行情CSV | M64: 股票日行情 | N64: ='300496.SZ_元数据'!$B$4 -> 45159 | O64: =ROW()-1 -> 63 | P64: =IFERROR(MATCH($N64,$B$2:$B$69,0),"") -> 64 | Q64: =IF(OR($P64="",$O64=""),"",$O64-$P64) -> -1 | R64: =IF($Q64="","",IF(AND($Q64>=-100,$Q64<=-1),"事件前100个交易日",IF(AND($Q64>=1,$Q64<=5),"事件后5个交易日",IF($Q64=0,"事件当日","其他区间")))) -> 事件前100个交易日
A65: 300496.SZ | B65: 45159 | C65: 80.01 | D65: 81.5 | E65: 79.85 | F65: 80.26 | G65: 80.42 | H65: -0.16 | I65: -0.199 | J65: 40220.38 | K65: 324091.71 | L65: ='300496.SZ_元数据'!$B$5 -> 事件库1.csv + 股票日行情CSV | M65: 股票日行情 | N65: ='300496.SZ_元数据'!$B$4 -> 45159 | O65: =ROW()-1 -> 64 | P65: =IFERROR(MATCH($N65,$B$2:$B$69,0),"") -> 64 | Q65: =IF(OR($P65="",$O65=""),"",$O65-$P65) -> 0 | R65: =IF($Q65="","",IF(AND($Q65>=-100,$Q65<=-1),"事件前100个交易日",IF(AND($Q65>=1,$Q65<=5),"事件后5个交易日",IF($Q65=0,"事件当日","其他区间")))) -> 事件当日 | S65: 原始事件日期非交易日，T0顺延至2023-08-21；事件前仅有63个交易日；事件后仅有4个交易日
A66: 300496.SZ | B66: 45160 | C66: 81 | D66: 81.46 | E66: 77.9 | F66: 80.78 | G66: 80.26 | H66: 0.52 | I66: 0.6479 | J66: 79807.63 | K66: 635112.17 | L66: ='300496.SZ_元数据'!$B$5 -> 事件库1.csv + 股票日行情CSV | M66: 股票日行情 | N66: ='300496.SZ_元数据'!$B$4 -> 45159 | O66: =ROW()-1 -> 65 | P66: =IFERROR(MATCH($N66,$B$2:$B$69,0),"") -> 64 | Q66: =IF(OR($P66="",$O66=""),"",$O66-$P66) -> 1 | R66: =IF($Q66="","",IF(AND($Q66>=-100,$Q66<=-1),"事件前100个交易日",IF(AND($Q66>=1,$Q66<=5),"事件后5个交易日",IF($Q66=0,"事件当日","其他区间")))) -> 事件后5个交易日
A67: 300496.SZ | B67: 45161 | C67: 80.61 | D67: 80.61 | E67: 77.1 | F67: 77.11 | G67: 80.78 | H67: -3.67 | I67: -4.5432 | J67: 60059.69 | K67: 470627.09 | L67: ='300496.SZ_元数据'!$B$5 -> 事件库1.csv + 股票日行情CSV | M67: 股票日行情 | N67: ='300496.SZ_元数据'!$B$4 -> 45159 | O67: =ROW()-1 -> 66 | P67: =IFERROR(MATCH($N67,$B$2:$B$69,0),"") -> 64 | Q67: =IF(OR($P67="",$O67=""),"",$O67-$P67) -> 2 | R67: =IF($Q67="","",IF(AND($Q67>=-100,$Q67<=-1),"事件前100个交易日",IF(AND($Q67>=1,$Q67<=5),"事件后5个交易日",IF($Q67=0,"事件当日","其他区间")))) -> 事件后5个交易日
A68: 300496.SZ | B68: 45162 | C68: 78 | D68: 78.96 | E68: 77.42 | F68: 77.45 | G68: 77.11 | H68: 0.34 | I68: 0.4409 | J68: 51280.17 | K68: 400481.76 | L68: ='300496.SZ_元数据'!$B$5 -> 事件库1.csv + 股票日行情CSV | M68: 股票日行情 | N68: ='300496.SZ_元数据'!$B$4 -> 45159 | O68: =ROW()-1 -> 67 | P68: =IFERROR(MATCH($N68,$B$2:$B$69,0),"") -> 64 | Q68: =IF(OR($P68="",$O68=""),"",$O68-$P68) -> 3 | R68: =IF($Q68="","",IF(AND($Q68>=-100,$Q68<=-1),"事件前100个交易日",IF(AND($Q68>=1,$Q68<=5),"事件后5个交易日",IF($Q68=0,"事件当日","其他区间")))) -> 事件后5个交易日
A69: 300496.SZ | B69: 45163 | C69: 76.9 | D69: 76.9 | E69: 74.11 | F69: 74.72 | G69: 77.45 | H69: -2.73 | I69: -3.5249 | J69: 66127.75 | K69: 498201.8 | L69: ='300496.SZ_元数据'!$B$5 -> 事件库1.csv + 股票日行情CSV | M69: 股票日行情 | N69: ='300496.SZ_元数据'!$B$4 -> 45159 | O69: =ROW()-1 -> 68 | P69: =IFERROR(MATCH($N69,$B$2:$B$69,0),"") -> 64 | Q69: =IF(OR($P69="",$O69=""),"",$O69-$P69) -> 4 | R69: =IF($Q69="","",IF(AND($Q69>=-100,$Q69<=-1),"事件前100个交易日",IF(AND($Q69>=1,$Q69<=5),"事件后5个交易日",IF($Q69=0,"事件当日","其他区间")))) -> 事件后5个交易日

Sheet 300571.SZ_元数据
A1: 字段 | B1: 内容
A2: 股票代码 | B2: 300571.SZ
A3: 事件名称 | B3: 平治信息： 关于陕西电信GPU算力建设项目进展暨签订框架协议的公告
A4: 事件日期 | B4: 45803
A5: 数据来源 | B5: 事件库1.csv + 股票日行情CSV
A6: 分类规则 | B6: 前100个交易日 / 后5个交易日
A7: 说明 | B7: 使用事件库匹配事件，并按事件日期定位 T0；若事件日非交易日，则顺延到下一交易日。
A8: 原始事件日期 | B8: 45803
A9: 事件ID | B9: 29
A10: 事件类型 | B10: 公司行为
A11: 行业 | B11: GPU
A12: 内容链接 | B12: https://www.cninfo.com.cn/new/disclosure/detail?orgId=9900029947&announcementId=1223682100&announcementTime=2025-05-26%2017:00
A13: 对齐说明 | B13: 已匹配

Sheet 300571.SZ_行情
A1: 代码 | B1: 日期 | C1: 开盘价 | D1: 最高价 | E1: 最低价 | F1: 收盘价 | G1: 昨日收盘价 | H1: 变化量 | I1: 涨跌幅 | J1: 成交量 | K1: 金额 | L1: 数据来源 | M1: 数据分类 | N1: 事件日期 | O1: 交易日序号 | P1: 事件交易日序号 | Q1: 相对交易日 | R1: 窗口标签 | S1: 备注
A2: 300571.SZ | B2: 45714 | C2: 36.68 | D2: 37.4 | E2: 35.76 | F2: 36.92 | G2: 36.68 | H2: 0.24 | I2: 0.6543 | J2: 143702.71 | K2: 526603.31 | L2: ='300571.SZ_元数据'!$B$5 -> 事件库1.csv + 股票日行情CSV | M2: 股票日行情 | N2: ='300571.SZ_元数据'!$B$4 -> 45803 | O2: =ROW()-1 -> 1 | P2: =IFERROR(MATCH($N2,$B$2:$B$65,0),"") -> 60 | Q2: =IF(OR($P2="",$O2=""),"",$O2-$P2) -> -59 | R2: =IF($Q2="","",IF(AND($Q2>=-100,$Q2<=-1),"事件前100个交易日",IF(AND($Q2>=1,$Q2<=5),"事件后5个交易日",IF($Q2=0,"事件当日","其他区间")))) -> 事件前100个交易日
A3: 300571.SZ | B3: 45715 | C3: 36.6 | D3: 39.12 | E3: 34.8 | F3: 38.19 | G3: 36.92 | H3: 1.27 | I3: 3.4399 | J3: 227485.96 | K3: 839919.05 | L3: ='300571.SZ_元数据'!$B$5 -> 事件库1.csv + 股票日行情CSV | M3: 股票日行情 | N3: ='300571.SZ_元数据'!$B$4 -> 45803 | O3: =ROW()-1 -> 2 | P3: =IFERROR(MATCH($N3,$B$2:$B$65,0),"") -> 60 | Q3: =IF(OR($P3="",$O3=""),"",$O3-$P3) -> -58 | R3: =IF($Q3="","",IF(AND($Q3>=-100,$Q3<=-1),"事件前100个交易日",IF(AND($Q3>=1,$Q3<=5),"事件后5个交易日",IF($Q3=0,"事件当日","其他区间")))) -> 事件前100个交易日
A4: 300571.SZ | B4: 45716 | C4: 37.69 | D4: 37.69 | E4: 33.33 | F4: 33.6 | G4: 38.19 | H4: -4.59 | I4: -12.0189 | J4: 155922.5 | K4: 549045.28 | L4: ='300571.SZ_元数据'!$B$5 -> 事件库1.csv + 股票日行情CSV | M4: 股票日行情 | N4: ='300571.SZ_元数据'!$B$4 -> 45803 | O4: =ROW()-1 -> 3 | P4: =IFERROR(MATCH($N4,$B$2:$B$65,0),"") -> 60 | Q4: =IF(OR($P4="",$O4=""),"",$O4-$P4) -> -57 | R4: =IF($Q4="","",IF(AND($Q4>=-100,$Q4<=-1),"事件前100个交易日",IF(AND($Q4>=1,$Q4<=5),"事件后5个交易日",IF($Q4=0,"事件当日","其他区间")))) -> 事件前100个交易日
A5: 300571.SZ | B5: 45719 | C5: 33.85 | D5: 34.06 | E5: 32 | F5: 32.6 | G5: 33.6 | H5: -1 | I5: -2.9762 | J5: 99991.08 | K5: 329220.36 | L5: ='300571.SZ_元数据'!$B$5 -> 事件库1.csv + 股票日行情CSV | M5: 股票日行情 | N5: ='300571.SZ_元数据'!$B$4 -> 45803 | O5: =ROW()-1 -> 4 | P5: =IFERROR(MATCH($N5,$B$2:$B$65,0),"") -> 60 | Q5: =IF(OR($P5="",$O5=""),"",$O5-$P5) -> -56 | R5: =IF($Q5="","",IF(AND($Q5>=-100,$Q5<=-1),"事件前100个交易日",IF(AND($Q5>=1,$Q5<=5),"事件后5个交易日",IF($Q5=0,"事件当日","其他区间")))) -> 事件前100个交易日
A6: 300571.SZ | B6: 45720 | C6: 32.18 | D6: 34.36 | E6: 31.81 | F6: 33.83 | G6: 32.6 | H6: 1.23 | I6: 3.773 | J6: 103739.59 | K6: 346002.41 | L6: ='300571.SZ_元数据'!$B$5 -> 事件库1.csv + 股票日行情CSV | M6: 股票日行情 | N6: ='300571.SZ_元数据'!$B$4 -> 45803 | O6: =ROW()-1 -> 5 | P6: =IFERROR(MATCH($N6,$B$2:$B$65,0),"") -> 60 | Q6: =IF(OR($P6="",$O6=""),"",$O6-$P6) -> -55 | R6: =IF($Q6="","",IF(AND($Q6>=-100,$Q6<=-1),"事件前100个交易日",IF(AND($Q6>=1,$Q6<=5),"事件后5个交易日",IF($Q6=0,"事件当日","其他区间")))) -> 事件前100个交易日
A7: 300571.SZ | B7: 45721 | C7: 35.08 | D7: 36.24 | E7: 34.65 | F7: 35.65 | G7: 33.83 | H7: 1.82 | I7: 5.3798 | J7: 142717.12 | K7: 505908.59 | L7: ='300571.SZ_元数据'!$B$5 -> 事件库1.csv + 股票日行情CSV | M7: 股票日行情 | N7: ='300571.SZ_元数据'!$B$4 -> 45803 | O7: =ROW()-1 -> 6 | P7: =IFERROR(MATCH($N7,$B$2:$B$65,0),"") -> 60 | Q7: =IF(OR($P7="",$O7=""),"",$O7-$P7) -> -54 | R7: =IF($Q7="","",IF(AND($Q7>=-100,$Q7<=-1),"事件前100个交易日",IF(AND($Q7>=1,$Q7<=5),"事件后5个交易日",IF($Q7=0,"事件当日","其他区间")))) -> 事件前100个交易日
A8: 300571.SZ | B8: 45722 | C8: 36.38 | D8: 38.2 | E8: 36.38 | F8: 37.91 | G8: 35.65 | H8: 2.26 | I8: 6.3394 | J8: 198111.04 | K8: 738385.41 | L8: ='300571.SZ_元数据'!$B$5 -> 事件库1.csv + 股票日行情CSV | M8: 股票日行情 | N8: ='300571.SZ_元数据'!$B$4 -> 45803 | O8: =ROW()-1 -> 7 | P8: =IFERROR(MATCH($N8,$B$2:$B$65,0),"") -> 60 | Q8: =IF(OR($P8="",$O8=""),"",$O8-$P8) -> -53 | R8: =IF($Q8="","",IF(AND($Q8>=-100,$Q8<=-1),"事件前100个交易日",IF(AND($Q8>=1,$Q8<=5),"事件后5个交易日",IF($Q8=0,"事件当日","其他区间")))) -> 事件前100个交易日
A9: 300571.SZ | B9: 45723 | C9: 36.66 | D9: 38.14 | E9: 35.88 | F9: 36.29 | G9: 37.91 | H9: -1.62 | I9: -4.2733 | J9: 150273.04 | K9: 555676.98 | L9: ='300571.SZ_元数据'!$B$5 -> 事件库1.csv + 股票日行情CSV | M9: 股票日行情 | N9: ='300571.SZ_元数据'!$B$4 -> 45803 | O9: =ROW()-1 -> 8 | P9: =IFERROR(MATCH($N9,$B$2:$B$65,0),"") -> 60 | Q9: =IF(OR($P9="",$O9=""),"",$O9-$P9) -> -52 | R9: =IF($Q9="","",IF(AND($Q9>=-100,$Q9<=-1),"事件前100个交易日",IF(AND($Q9>=1,$Q9<=5),"事件后5个交易日",IF($Q9=0,"事件当日","其他区间")))) -> 事件前100个交易日
A10: 300571.SZ | B10: 45726 | C10: 35.71 | D10: 36 | E10: 34.81 | F10: 35.66 | G10: 36.29 | H10: -0.63 | I10: -1.736 | J10: 84833 | K10: 299930.75 | L10: ='300571.SZ_元数据'!$B$5 -> 事件库1.csv + 股票日行情CSV | M10: 股票日行情 | N10: ='300571.SZ_元数据'!$B$4 -> 45803 | O10: =ROW()-1 -> 9 | P10: =IFERROR(MATCH($N10,$B$2:$B$65,0),"") -> 60 | Q10: =IF(OR($P10="",$O10=""),"",$O10-$P10) -> -51 | R10: =IF($Q10="","",IF(AND($Q10>=-100,$Q10<=-1),"事件前100个交易日",IF(AND($Q10>=1,$Q10<=5),"事件后5个交易日",IF($Q10=0,"事件当日","其他区间")))) -> 事件前100个交易日
A11: 300571.SZ | B11: 45727 | C11: 34.63 | D11: 35.6 | E11: 34.42 | F11: 35.24 | G11: 35.66 | H11: -0.42 | I11: -1.1778 | J11: 65993.28 | K11: 230738.9 | L11: ='300571.SZ_元数据'!$B$5 -> 事件库1.csv + 股票日行情CSV | M11: 股票日行情 | N11: ='300571.SZ_元数据'!$B$4 -> 45803 | O11: =ROW()-1 -> 10 | P11: =IFERROR(MATCH($N11,$B$2:$B$65,0),"") -> 60 | Q11: =IF(OR($P11="",$O11=""),"",$O11-$P11) -> -50 | R11: =IF($Q11="","",IF(AND($Q11>=-100,$Q11<=-1),"事件前100个交易日",IF(AND($Q11>=1,$Q11<=5),"事件后5个交易日",IF($Q11=0,"事件当日","其他区间")))) -> 事件前100个交易日
A12: 300571.SZ | B12: 45728 | C12: 36 | D12: 38.98 | E12: 36 | F12: 37.77 | G12: 35.24 | H12: 2.53 | I12: 7.1793 | J12: 198552.6 | K12: 741708.99 | L12: ='300571.SZ_元数据'!$B$5 -> 事件库1.csv + 股票日行情CSV | M12: 股票日行情 | N12: ='300571.SZ_元数据'!$B$4 -> 45803 | O12: =ROW()-1 -> 11 | P12: =IFERROR(MATCH($N12,$B$2:$B$65,0),"") -> 60 | Q12: =IF(OR($P12="",$O12=""),"",$O12-$P12) -> -49 | R12: =IF($Q12="","",IF(AND($Q12>=-100,$Q12<=-1),"事件前100个交易日",IF(AND($Q12>=1,$Q12<=5),"事件后5个交易日",IF($Q12=0,"事件当日","其他区间")))) -> 事件前100个交易日
A13: 300571.SZ | B13: 45729 | C13: 37.17 | D13: 37.76 | E13: 35.1 | F13: 36.08 | G13: 37.77 | H13: -1.69 | I13: -4.4745 | J13: 137214.67 | K13: 495057.62 | L13: ='300571.SZ_元数据'!$B$5 -> 事件库1.csv + 股票日行情CSV | M13: 股票日行情 | N13: ='300571.SZ_元数据'!$B$4 -> 45803 | O13: =ROW()-1 -> 12 | P13: =IFERROR(MATCH($N13,$B$2:$B$65,0),"") -> 60 | Q13: =IF(OR($P13="",$O13=""),"",$O13-$P13) -> -48 | R13: =IF($Q13="","",IF(AND($Q13>=-100,$Q13<=-1),"事件前100个交易日",IF(AND($Q13>=1,$Q13<=5),"事件后5个交易日",IF($Q13=0,"事件当日","其他区间")))) -> 事件前100个交易日
... A60: 300571.SZ | B60: 45800 | C60: 30.66 | D60: 30.79 | E60: 29.73 | F60: 29.77 | G60: 30.7 | H60: -0.93 | I60: -3.0293 | J60: 50668.36 | K60: 153008.55 | L60: ='300571.SZ_元数据'!$B$5 -> 事件库1.csv + 股票日行情CSV | M60: 股票日行情 | N60: ='300571.SZ_元数据'!$B$4 -> 45803 | O60: =ROW()-1 -> 59 | P60: =IFERROR(MATCH($N60,$B$2:$B$65,0),"") -> 60 | Q60: =IF(OR($P60="",$O60=""),"",$O60-$P60) -> -1 | R60: =IF($Q60="","",IF(AND($Q60>=-100,$Q60<=-1),"事件前100个交易日",IF(AND($Q60>=1,$Q60<=5),"事件后5个交易日",IF($Q60=0,"事件当日","其他区间")))) -> 事件前100个交易日
A61: 300571.SZ | B61: 45803 | C61: 30.15 | D61: 30.65 | E61: 29.77 | F61: 30.5 | G61: 29.77 | H61: 0.73 | I61: 2.4521 | J61: 42921 | K61: 129940.13 | L61: ='300571.SZ_元数据'!$B$5 -> 事件库1.csv + 股票日行情CSV | M61: 股票日行情 | N61: ='300571.SZ_元数据'!$B$4 -> 45803 | O61: =ROW()-1 -> 60 | P61: =IFERROR(MATCH($N61,$B$2:$B$65,0),"") -> 60 | Q61: =IF(OR($P61="",$O61=""),"",$O61-$P61) -> 0 | R61: =IF($Q61="","",IF(AND($Q61>=-100,$Q61<=-1),"事件前100个交易日",IF(AND($Q61>=1,$Q61<=5),"事件后5个交易日",IF($Q61=0,"事件当日","其他区间")))) -> 事件当日 | S61: 原始事件日期非交易日，T0顺延至2025-05-26；事件前仅有59个交易日；事件后仅有4个交易日
A62: 300571.SZ | B62: 45804 | C62: 31.44 | D62: 31.8 | E62: 30.64 | F62: 30.76 | G62: 30.5 | H62: 0.26 | I62: 0.8525 | J62: 83419.63 | K62: 258388.45 | L62: ='300571.SZ_元数据'!$B$5 -> 事件库1.csv + 股票日行情CSV | M62: 股票日行情 | N62: ='300571.SZ_元数据'!$B$4 -> 45803 | O62: =ROW()-1 -> 61 | P62: =IFERROR(MATCH($N62,$B$2:$B$65,0),"") -> 60 | Q62: =IF(OR($P62="",$O62=""),"",$O62-$P62) -> 1 | R62: =IF($Q62="","",IF(AND($Q62>=-100,$Q62<=-1),"事件前100个交易日",IF(AND($Q62>=1,$Q62<=5),"事件后5个交易日",IF($Q62=0,"事件当日","其他区间")))) -> 事件后5个交易日
A63: 300571.SZ | B63: 45805 | C63: 30.89 | D63: 31.3 | E63: 29.89 | F63: 31.11 | G63: 30.76 | H63: 0.35 | I63: 1.1378 | J63: 75504 | K63: 232007.28 | L63: ='300571.SZ_元数据'!$B$5 -> 事件库1.csv + 股票日行情CSV | M63: 股票日行情 | N63: ='300571.SZ_元数据'!$B$4 -> 45803 | O63: =ROW()-1 -> 62 | P63: =IFERROR(MATCH($N63,$B$2:$B$65,0),"") -> 60 | Q63: =IF(OR($P63="",$O63=""),"",$O63-$P63) -> 2 | R63: =IF($Q63="","",IF(AND($Q63>=-100,$Q63<=-1),"事件前100个交易日",IF(AND($Q63>=1,$Q63<=5),"事件后5个交易日",IF($Q63=0,"事件当日","其他区间")))) -> 事件后5个交易日
A64: 300571.SZ | B64: 45806 | C64: 30.5 | D64: 31.47 | E64: 30.5 | F64: 31.39 | G64: 31.11 | H64: 0.28 | I64: 0.9 | J64: 71312.85 | K64: 222048.13 | L64: ='300571.SZ_元数据'!$B$5 -> 事件库1.csv + 股票日行情CSV | M64: 股票日行情 | N64: ='300571.SZ_元数据'!$B$4 -> 45803 | O64: =ROW()-1 -> 63 | P64: =IFERROR(MATCH($N64,$B$2:$B$65,0),"") -> 60 | Q64: =IF(OR($P64="",$O64=""),"",$O64-$P64) -> 3 | R64: =IF($Q64="","",IF(AND($Q64>=-100,$Q64<=-1),"事件前100个交易日",IF(AND($Q64>=1,$Q64<=5),"事件后5个交易日",IF($Q64=0,"事件当日","其他区间")))) -> 事件后5个交易日
A65: 300571.SZ | B65: 45807 | C65: 31.07 | D65: 31.27 | E65: 29.91 | F65: 30.05 | G65: 31.39 | H65: -1.34 | I65: -4.2689 | J65: 58120.99 | K65: 176436.06 | L65: ='300571.SZ_元数据'!$B$5 -> 事件库1.csv + 股票日行情CSV | M65: 股票日行情 | N65: ='300571.SZ_元数据'!$B$4 -> 45803 | O65: =ROW()-1 -> 64 | P65: =IFERROR(MATCH($N65,$B$2:$B$65,0),"") -> 60 | Q65: =IF(OR($P65="",$O65=""),"",$O65-$P65) -> 4 | R65: =IF($Q65="","",IF(AND($Q65>=-100,$Q65<=-1),"事件前100个交易日",IF(AND($Q65>=1,$Q65<=5),"事件后5个交易日",IF($Q65=0,"事件当日","其他区间")))) -> 事件后5个交易日

Sheet 300638.SZ_元数据
A1: 字段 | B1: 内容
A2: 股票代码 | B2: 300638.SZ
A3: 事件名称 | B3: 深度报告：5G+AI时代下的连接与边缘计算旗手
A4: 事件日期 | B4: 45063
A5: 数据来源 | B5: 事件库1.csv + 股票日行情CSV
A6: 分类规则 | B6: 前100个交易日 / 后5个交易日
A7: 说明 | B7: 使用事件库匹配事件，并按事件日期定位 T0；若事件日非交易日，则顺延到下一交易日。
A8: 原始事件日期 | B8: 45063
A9: 事件ID | B9: 36
A10: 事件类型 | B10: 技术
A11: 行业 | B11: 边缘计算
A12: 内容链接 | B12: http://data.eastmoney.com/report/zw_stock.jshtml?infocode=AP202305171586714987
A13: 对齐说明 | B13: 已匹配

Sheet 300638.SZ_行情
A1: 代码 | B1: 日期 | C1: 开盘价 | D1: 最高价 | E1: 最低价 | F1: 收盘价 | G1: 昨日收盘价 | H1: 变化量 | I1: 涨跌幅 | J1: 成交量 | K1: 金额 | L1: 数据来源 | M1: 数据分类 | N1: 事件日期 | O1: 交易日序号 | P1: 事件交易日序号 | Q1: 相对交易日 | R1: 窗口标签 | S1: 备注
A2: 300638.SZ | B2: 44974 | C2: 23.22 | D2: 23.49 | E2: 21.86 | F2: 22 | G2: 23.2 | H2: -1.2 | I2: -5.1724 | J2: 149893.17 | K2: 335403.76 | L2: ='300638.SZ_元数据'!$B$5 -> 事件库1.csv + 股票日行情CSV | M2: 股票日行情 | N2: ='300638.SZ_元数据'!$B$4 -> 45063 | O2: =ROW()-1 -> 1 | P2: =IFERROR(MATCH($N2,$B$2:$B$64,0),"") -> 60 | Q2: =IF(OR($P2="",$O2=""),"",$O2-$P2) -> -59 | R2: =IF($Q2="","",IF(AND($Q2>=-100,$Q2<=-1),"事件前100个交易日",IF(AND($Q2>=1,$Q2<=5),"事件后5个交易日",IF($Q2=0,"事件当日","其他区间")))) -> 事件前100个交易日
A3: 300638.SZ | B3: 44977 | C3: 22.14 | D3: 22.88 | E3: 21.63 | F3: 22.65 | G3: 22 | H3: 0.65 | I3: 2.9545 | J3: 94186.03 | K3: 211146.41 | L3: ='300638.SZ_元数据'!$B$5 -> 事件库1.csv + 股票日行情CSV | M3: 股票日行情 | N3: ='300638.SZ_元数据'!$B$4 -> 45063 | O3: =ROW()-1 -> 2 | P3: =IFERROR(MATCH($N3,$B$2:$B$64,0),"") -> 60 | Q3: =IF(OR($P3="",$O3=""),"",$O3-$P3) -> -58 | R3: =IF($Q3="","",IF(AND($Q3>=-100,$Q3<=-1),"事件前100个交易日",IF(AND($Q3>=1,$Q3<=5),"事件后5个交易日",IF($Q3=0,"事件当日","其他区间")))) -> 事件前100个交易日
A4: 300638.SZ | B4: 44978 | C4: 22.9 | D4: 23.27 | E4: 22.46 | F4: 22.71 | G4: 22.65 | H4: 0.06 | I4: 0.2649 | J4: 67562.53 | K4: 154159.63 | L4: ='300638.SZ_元数据'!$B$5 -> 事件库1.csv + 股票日行情CSV | M4: 股票日行情 | N4: ='300638.SZ_元数据'!$B$4 -> 45063 | O4: =ROW()-1 -> 3 | P4: =IFERROR(MATCH($N4,$B$2:$B$64,0),"") -> 60 | Q4: =IF(OR($P4="",$O4=""),"",$O4-$P4) -> -57 | R4: =IF($Q4="","",IF(AND($Q4>=-100,$Q4<=-1),"事件前100个交易日",IF(AND($Q4>=1,$Q4<=5),"事件后5个交易日",IF($Q4=0,"事件当日","其他区间")))) -> 事件前100个交易日
A5: 300638.SZ | B5: 44979 | C5: 22.44 | D5: 22.61 | E5: 22 | F5: 22.24 | G5: 22.71 | H5: -0.47 | I5: -2.0696 | J5: 64654.8 | K5: 143772.24 | L5: ='300638.SZ_元数据'!$B$5 -> 事件库1.csv + 股票日行情CSV | M5: 股票日行情 | N5: ='300638.SZ_元数据'!$B$4 -> 45063 | O5: =ROW()-1 -> 4 | P5: =IFERROR(MATCH($N5,$B$2:$B$64,0),"") -> 60 | Q5: =IF(OR($P5="",$O5=""),"",$O5-$P5) -> -56 | R5: =IF($Q5="","",IF(AND($Q5>=-100,$Q5<=-1),"事件前100个交易日",IF(AND($Q5>=1,$Q5<=5),"事件后5个交易日",IF($Q5=0,"事件当日","其他区间")))) -> 事件前100个交易日
A6: 300638.SZ | B6: 44980 | C6: 22.37 | D6: 22.37 | E6: 21.58 | F6: 21.69 | G6: 22.24 | H6: -0.55 | I6: -2.473 | J6: 62734.37 | K6: 137179.91 | L6: ='300638.SZ_元数据'!$B$5 -> 事件库1.csv + 股票日行情CSV | M6: 股票日行情 | N6: ='300638.SZ_元数据'!$B$4 -> 45063 | O6: =ROW()-1 -> 5 | P6: =IFERROR(MATCH($N6,$B$2:$B$64,0),"") -> 60 | Q6: =IF(OR($P6="",$O6=""),"",$O6-$P6) -> -55 | R6: =IF($Q6="","",IF(AND($Q6>=-100,$Q6<=-1),"事件前100个交易日",IF(AND($Q6>=1,$Q6<=5),"事件后5个交易日",IF($Q6=0,"事件当日","其他区间")))) -> 事件前100个交易日
A7: 300638.SZ | B7: 44981 | C7: 21.8 | D7: 22.18 | E7: 21.6 | F7: 21.69 | G7: 21.69 | H7: 0 | I7: 0 | J7: 45374.59 | K7: 98971.446 | L7: ='300638.SZ_元数据'!$B$5 -> 事件库1.csv + 股票日行情CSV | M7: 股票日行情 | N7: ='300638.SZ_元数据'!$B$4 -> 45063 | O7: =ROW()-1 -> 6 | P7: =IFERROR(MATCH($N7,$B$2:$B$64,0),"") -> 60 | Q7: =IF(OR($P7="",$O7=""),"",$O7-$P7) -> -54 | R7: =IF($Q7="","",IF(AND($Q7>=-100,$Q7<=-1),"事件前100个交易日",IF(AND($Q7>=1,$Q7<=5),"事件后5个交易日",IF($Q7=0,"事件当日","其他区间")))) -> 事件前100个交易日
A8: 300638.SZ | B8: 44984 | C8: 21.51 | D8: 21.62 | E8: 20.95 | F8: 21.05 | G8: 21.69 | H8: -0.64 | I8: -2.9507 | J8: 72683.68 | K8: 153945.96 | L8: ='300638.SZ_元数据'!$B$5 -> 事件库1.csv + 股票日行情CSV | M8: 股票日行情 | N8: ='300638.SZ_元数据'!$B$4 -> 45063 | O8: =ROW()-1 -> 7 | P8: =IFERROR(MATCH($N8,$B$2:$B$64,0),"") -> 60 | Q8: =IF(OR($P8="",$O8=""),"",$O8-$P8) -> -53 | R8: =IF($Q8="","",IF(AND($Q8>=-100,$Q8<=-1),"事件前100个交易日",IF(AND($Q8>=1,$Q8<=5),"事件后5个交易日",IF($Q8=0,"事件当日","其他区间")))) -> 事件前100个交易日
A9: 300638.SZ | B9: 44985 | C9: 21.45 | D9: 21.8 | E9: 21.17 | F9: 21.49 | G9: 21.05 | H9: 0.44 | I9: 2.0903 | J9: 56654.66 | K9: 121628.62 | L9: ='300638.SZ_元数据'!$B$5 -> 事件库1.csv + 股票日行情CSV | M9: 股票日行情 | N9: ='300638.SZ_元数据'!$B$4 -> 45063 | O9: =ROW()-1 -> 8 | P9: =IFERROR(MATCH($N9,$B$2:$B$64,0),"") -> 60 | Q9: =IF(OR($P9="",$O9=""),"",$O9-$P9) -> -52 | R9: =IF($Q9="","",IF(AND($Q9>=-100,$Q9<=-1),"事件前100个交易日",IF(AND($Q9>=1,$Q9<=5),"事件后5个交易日",IF($Q9=0,"事件当日","其他区间")))) -> 事件前100个交易日
A10: 300638.SZ | B10: 44986 | C10: 21.46 | D10: 23.02 | E10: 21.35 | F10: 22.74 | G10: 21.49 | H10: 1.25 | I10: 5.8167 | J10: 129180.5 | K10: 290397.64 | L10: ='300638.SZ_元数据'!$B$5 -> 事件库1.csv + 股票日行情CSV | M10: 股票日行情 | N10: ='300638.SZ_元数据'!$B$4 -> 45063 | O10: =ROW()-1 -> 9 | P10: =IFERROR(MATCH($N10,$B$2:$B$64,0),"") -> 60 | Q10: =IF(OR($P10="",$O10=""),"",$O10-$P10) -> -51 | R10: =IF($Q10="","",IF(AND($Q10>=-100,$Q10<=-1),"事件前100个交易日",IF(AND($Q10>=1,$Q10<=5),"事件后5个交易日",IF($Q10=0,"事件当日","其他区间")))) -> 事件前100个交易日
A11: 300638.SZ | B11: 44987 | C11: 23.23 | D11: 24.16 | E11: 23.04 | F11: 23.3 | G11: 22.74 | H11: 0.56 | I11: 2.4626 | J11: 157023.51 | K11: 368227.28 | L11: ='300638.SZ_元数据'!$B$5 -> 事件库1.csv + 股票日行情CSV | M11: 股票日行情 | N11: ='300638.SZ_元数据'!$B$4 -> 45063 | O11: =ROW()-1 -> 10 | P11: =IFERROR(MATCH($N11,$B$2:$B$64,0),"") -> 60 | Q11: =IF(OR($P11="",$O11=""),"",$O11-$P11) -> -50 | R11: =IF($Q11="","",IF(AND($Q11>=-100,$Q11<=-1),"事件前100个交易日",IF(AND($Q11>=1,$Q11<=5),"事件后5个交易日",IF($Q11=0,"事件当日","其他区间")))) -> 事件前100个交易日
A12: 300638.SZ | B12: 44988 | C12: 23.01 | D12: 23.15 | E12: 22.17 | F12: 22.62 | G12: 23.3 | H12: -0.68 | I12: -2.9185 | J12: 134082.22 | K12: 303874.78 | L12: ='300638.SZ_元数据'!$B$5 -> 事件库1.csv + 股票日行情CSV | M12: 股票日行情 | N12: ='300638.SZ_元数据'!$B$4 -> 45063 | O12: =ROW()-1 -> 11 | P12: =IFERROR(MATCH($N12,$B$2:$B$64,0),"") -> 60 | Q12: =IF(OR($P12="",$O12=""),"",$O12-$P12) -> -49 | R12: =IF($Q12="","",IF(AND($Q12>=-100,$Q12<=-1),"事件前100个交易日",IF(AND($Q12>=1,$Q12<=5),"事件后5个交易日",IF($Q12=0,"事件当日","其他区间")))) -> 事件前100个交易日
A13: 300638.SZ | B13: 44991 | C13: 22.78 | D13: 22.99 | E13: 22.2 | F13: 22.26 | G13: 22.62 | H13: -0.36 | I13: -1.5915 | J13: 82476.52 | K13: 186366.28 | L13: ='300638.SZ_元数据'!$B$5 -> 事件库1.csv + 股票日行情CSV | M13: 股票日行情 | N13: ='300638.SZ_元数据'!$B$4 -> 45063 | O13: =ROW()-1 -> 12 | P13: =IFERROR(MATCH($N13,$B$2:$B$64,0),"") -> 60 | Q13: =IF(OR($P13="",$O13=""),"",$O13-$P13) -> -48 | R13: =IF($Q13="","",IF(AND($Q13>=-100,$Q13<=-1),"事件前100个交易日",IF(AND($Q13>=1,$Q13<=5),"事件后5个交易日",IF($Q13=0,"事件当日","其他区间")))) -> 事件前100个交易日
... A60: 300638.SZ | B60: 45062 | C60: 22.85 | D60: 22.88 | E60: 21.92 | F60: 22.12 | G60: 22.85 | H60: -0.73 | I60: -3.1947 | J60: 87374.54 | K60: 193826.95 | L60: ='300638.SZ_元数据'!$B$5 -> 事件库1.csv + 股票日行情CSV | M60: 股票日行情 | N60: ='300638.SZ_元数据'!$B$4 -> 45063 | O60: =ROW()-1 -> 59 | P60: =IFERROR(MATCH($N60,$B$2:$B$64,0),"") -> 60 | Q60: =IF(OR($P60="",$O60=""),"",$O60-$P60) -> -1 | R60: =IF($Q60="","",IF(AND($Q60>=-100,$Q60<=-1),"事件前100个交易日",IF(AND($Q60>=1,$Q60<=5),"事件后5个交易日",IF($Q60=0,"事件当日","其他区间")))) -> 事件前100个交易日
A61: 300638.SZ | B61: 45063 | C61: 22.1 | D61: 22.38 | E61: 21.92 | F61: 22.27 | G61: 22.12 | H61: 0.15 | I61: 0.6781 | J61: 62100.47 | K61: 137605.2 | L61: ='300638.SZ_元数据'!$B$5 -> 事件库1.csv + 股票日行情CSV | M61: 股票日行情 | N61: ='300638.SZ_元数据'!$B$4 -> 45063 | O61: =ROW()-1 -> 60 | P61: =IFERROR(MATCH($N61,$B$2:$B$64,0),"") -> 60 | Q61: =IF(OR($P61="",$O61=""),"",$O61-$P61) -> 0 | R61: =IF($Q61="","",IF(AND($Q61>=-100,$Q61<=-1),"事件前100个交易日",IF(AND($Q61>=1,$Q61<=5),"事件后5个交易日",IF($Q61=0,"事件当日","其他区间")))) -> 事件当日 | S61: 原始事件日期非交易日，T0顺延至2023-05-17；事件前仅有59个交易日；事件后仅有3个交易日
A62: 300638.SZ | B62: 45064 | C62: 22.51 | D62: 25.08 | E62: 22.51 | F62: 24.47 | G62: 22.27 | H62: 2.2 | I62: 9.8788 | J62: 293601.88 | K62: 709315.94 | L62: ='300638.SZ_元数据'!$B$5 -> 事件库1.csv + 股票日行情CSV | M62: 股票日行情 | N62: ='300638.SZ_元数据'!$B$4 -> 45063 | O62: =ROW()-1 -> 61 | P62: =IFERROR(MATCH($N62,$B$2:$B$64,0),"") -> 60 | Q62: =IF(OR($P62="",$O62=""),"",$O62-$P62) -> 1 | R62: =IF($Q62="","",IF(AND($Q62>=-100,$Q62<=-1),"事件前100个交易日",IF(AND($Q62>=1,$Q62<=5),"事件后5个交易日",IF($Q62=0,"事件当日","其他区间")))) -> 事件后5个交易日
A63: 300638.SZ | B63: 45065 | C63: 24.24 | D63: 26.46 | E63: 24.2 | F63: 26.01 | G63: 24.47 | H63: 1.54 | I63: 6.2934 | J63: 379438.94 | K63: 965817.58 | L63: ='300638.SZ_元数据'!$B$5 -> 事件库1.csv + 股票日行情CSV | M63: 股票日行情 | N63: ='300638.SZ_元数据'!$B$4 -> 45063 | O63: =ROW()-1 -> 62 | P63: =IFERROR(MATCH($N63,$B$2:$B$64,0),"") -> 60 | Q63: =IF(OR($P63="",$O63=""),"",$O63-$P63) -> 2 | R63: =IF($Q63="","",IF(AND($Q63>=-100,$Q63<=-1),"事件前100个交易日",IF(AND($Q63>=1,$Q63<=5),"事件后5个交易日",IF($Q63=0,"事件当日","其他区间")))) -> 事件后5个交易日
A64: 300638.SZ | B64: 45068 | C64: 25.55 | D64: 26.22 | E64: 25.02 | F64: 26.04 | G64: 26.01 | H64: 0.03 | I64: 0.1153 | J64: 235978.63 | K64: 611342.37 | L64: ='300638.SZ_元数据'!$B$5 -> 事件库1.csv + 股票日行情CSV | M64: 股票日行情 | N64: ='300638.SZ_元数据'!$B$4 -> 45063 | O64: =ROW()-1 -> 63 | P64: =IFERROR(MATCH($N64,$B$2:$B$64,0),"") -> 60 | Q64: =IF(OR($P64="",$O64=""),"",$O64-$P64) -> 3 | R64: =IF($Q64="","",IF(AND($Q64>=-100,$Q64<=-1),"事件前100个交易日",IF(AND($Q64>=1,$Q64<=5),"事件后5个交易日",IF($Q64=0,"事件当日","其他区间")))) -> 事件后5个交易日

Sheet 300738.SZ_元数据
A1: 字段 | B1: 内容
A2: 股票代码 | B2: 300738.SZ
A3: 事件名称 | B3: 关于数据中心获得2023年度碳中和认证的公告
A4: 事件日期 | B4: 45532
A5: 数据来源 | B5: 事件库1.csv + 股票日行情CSV
A6: 分类规则 | B6: 前100个交易日 / 后5个交易日
A7: 说明 | B7: 使用事件库匹配事件，并按事件日期定位 T0；若事件日非交易日，则顺延到下一交易日。
A8: 原始事件日期 | B8: 45532
A9: 事件ID | B9: 40
A10: 事件类型 | B10: 公司行为
A11: 行业 | B11: 数据中心
A12: 内容链接 | B12: https://www.cninfo.com.cn/new/disclosure/detail?orgId=gfbj0832745&announcementId=1221004685&announcementTime=2024-08-28
A13: 对齐说明 | B13: 已匹配

Sheet 300738.SZ_行情
A1: 代码 | B1: 日期 | C1: 开盘价 | D1: 最高价 | E1: 最低价 | F1: 收盘价 | G1: 昨日收盘价 | H1: 变化量 | I1: 涨跌幅 | J1: 成交量 | K1: 金额 | L1: 数据来源 | M1: 数据分类 | N1: 事件日期 | O1: 交易日序号 | P1: 事件交易日序号 | Q1: 相对交易日 | R1: 窗口标签 | S1: 备注
A2: 300738.SZ | B2: 45440 | C2: 11.33 | D2: 11.47 | E2: 11.1 | F2: 11.11 | G2: 11.55 | H2: -0.44 | I2: -3.8095 | J2: 444352.72 | K2: 499574.56 | L2: ='300738.SZ_元数据'!$B$5 -> 事件库1.csv + 股票日行情CSV | M2: 股票日行情 | N2: ='300738.SZ_元数据'!$B$4 -> 45532 | O2: =ROW()-1 -> 1 | P2: =IFERROR(MATCH($N2,$B$2:$B$72,0),"") -> 66 | Q2: =IF(OR($P2="",$O2=""),"",$O2-$P2) -> -65 | R2: =IF($Q2="","",IF(AND($Q2>=-100,$Q2<=-1),"事件前100个交易日",IF(AND($Q2>=1,$Q2<=5),"事件后5个交易日",IF($Q2=0,"事件当日","其他区间")))) -> 事件前100个交易日
A3: 300738.SZ | B3: 45441 | C3: 11.09 | D3: 11.43 | E3: 11 | F3: 11.18 | G3: 11.11 | H3: 0.07 | I3: 0.6301 | J3: 366795.14 | K3: 409729.51 | L3: ='300738.SZ_元数据'!$B$5 -> 事件库1.csv + 股票日行情CSV | M3: 股票日行情 | N3: ='300738.SZ_元数据'!$B$4 -> 45532 | O3: =ROW()-1 -> 2 | P3: =IFERROR(MATCH($N3,$B$2:$B$72,0),"") -> 66 | Q3: =IF(OR($P3="",$O3=""),"",$O3-$P3) -> -64 | R3: =IF($Q3="","",IF(AND($Q3>=-100,$Q3<=-1),"事件前100个交易日",IF(AND($Q3>=1,$Q3<=5),"事件后5个交易日",IF($Q3=0,"事件当日","其他区间")))) -> 事件前100个交易日
A4: 300738.SZ | B4: 45442 | C4: 11.02 | D4: 11.06 | E4: 10.75 | F4: 10.81 | G4: 11.18 | H4: -0.37 | I4: -3.3095 | J4: 414145.87 | K4: 449474.26 | L4: ='300738.SZ_元数据'!$B$5 -> 事件库1.csv + 股票日行情CSV | M4: 股票日行情 | N4: ='300738.SZ_元数据'!$B$4 -> 45532 | O4: =ROW()-1 -> 3 | P4: =IFERROR(MATCH($N4,$B$2:$B$72,0),"") -> 66 | Q4: =IF(OR($P4="",$O4=""),"",$O4-$P4) -> -63 | R4: =IF($Q4="","",IF(AND($Q4>=-100,$Q4<=-1),"事件前100个交易日",IF(AND($Q4>=1,$Q4<=5),"事件后5个交易日",IF($Q4=0,"事件当日","其他区间")))) -> 事件前100个交易日
A5: 300738.SZ | B5: 45443 | C5: 10.78 | D5: 11.27 | E5: 10.78 | F5: 11.01 | G5: 10.81 | H5: 0.2 | I5: 1.8501 | J5: 419579.55 | K5: 464175.6 | L5: ='300738.SZ_元数据'!$B$5 -> 事件库1.csv + 股票日行情CSV | M5: 股票日行情 | N5: ='300738.SZ_元数据'!$B$4 -> 45532 | O5: =ROW()-1 -> 4 | P5: =IFERROR(MATCH($N5,$B$2:$B$72,0),"") -> 66 | Q5: =IF(OR($P5="",$O5=""),"",$O5-$P5) -> -62 | R5: =IF($Q5="","",IF(AND($Q5>=-100,$Q5<=-1),"事件前100个交易日",IF(AND($Q5>=1,$Q5<=5),"事件后5个交易日",IF($Q5=0,"事件当日","其他区间")))) -> 事件前100个交易日
